Workbook

Sheet README
A1: WENDY 7 - final2 (on hold, not submitted): actuarial assumptions and feature map
A2: This version | B2: Model run 'c5' of R/4_models_iterwendy07.R (models/wendy_iteration_07/c5/). All its changes are baked into the input sheets; sheet Changes_vs_WENDY4 lists each one with its reason and measured effect.
A3: How to run | B3: ASSUMPTIONS_XLSX=docs/assumptions_wendy07_final2.xlsx FINAL_FIT=1 FINAL_METHODS=all RUN_TAG=<tag> Rscript R/4_models_iterwendy07.R (no FEATURE_EDITS / SPEC_EDITS / IBNR_* / BAGS / METHOD_MIX needed). Then R/4_final_wendy07.R blends with SAM 3.
A4: Changes vs WENDY 4 | B4: See sheet Changes_vs_WENDY4. Full reasoning per step: docs/wendy07_experiment_log.md; every try: docs/wendy07_experiment_register.xlsx.
A5: Orange cells | B5: Cells changed from the WENDY 4 workbook (feature codes, Model_Spec, Settings).
A6: Line blend | B6: The submitted prediction is a per-line blend with SAM 3 (sheet SAM3_Blend); this workbook drives the WENDY 7 part.
A7: Submission file | B7: output/submission/submission_20261022_2328_wendy07_final2.csv (MD5 99135ba796a021c92c186e3e7bf71d3f)
A8: Model per peril | B8: Model_Spec: frequency = Poisson GBM (exposure x reported share as volume); severity = Gamma GBM (data-rich perils) or Gamma GLM on few factors (sparse/heavy perils); Tweedie GBM challenger; 'auto' selection keeps the better one per peril on the two validation folds.
A9: --- WENDY 4 notes (still valid unless changed above) ---
A10: Purpose | B10: One place for every target, data and feature decision behind iteration WENDY 4. The R script R/4_models_iterwendy04.R READS this workbook: sheets Features_*, Model_Spec, Structural_Zeros and Settings drive the model. Edit them here, re-run the script, compare scores.
A11: Where to save | B11: docs/assumptions_wendy04.xlsx in the repo (or set env var ASSUMPTIONS_XLSX to another path).
A12: Editable cells | B12: Blue text on yellow fill = inputs the script reads. Everything else is documentation.
A13: Feature codes | B13: In Features_<line>, each peril column holds: F = frequency model only, S = severity model only, B = both, - = not used. A feature is used only if its 'use' cell is Y.
A14: decision column | B14: Include = actuarial rationale, kept. Test = plausible but unproven, kept only if validation supports it (set use = N to drop). Exclude = no mechanism, noise, leakage, circular or duplicate.
A15: mono_freq / mono_sev | B15: Monotone constraint for numeric/boolean features: 1 = can only increase, -1 = can only decrease, 0 = free. Ignored for text categories.
A16: Model per peril | B16: Model_Spec: frequency = Poisson GBM (exposure x reported share as volume); severity = Gamma GBM (data-rich perils) or Gamma GLM on few factors (sparse/heavy perils); Tweedie GBM challenger; 'auto' selection keeps the better one per peril on the two validation folds.
A17: Validation | B17: Two out-of-time folds: fit 2021-22 -> score 2023, fit 2021-23 -> score 2024. Actuals are DEVELOPED (divided by the row's reported share) so models that predict ultimate cost are not penalised - this fixes the WENDY 3 scoring bias.
A18: Example row | B18: Features_Motor row 'ncb_years': decision Include, use Y, mono_freq -1, codes F F F - - (frequency of own damage, third-party property, bodily injury).
A19: Changes vs WENDY 3 | B19: 1) Frequency x severity per peril instead of one Tweedie per peril; 2) IBNR as a frequency offset, not a target uplift; 3) severity trend to the prediction year; 4) outlier claim limit before capping; 5) per-peril feature lists (noise, marketing and circular columns removed); 6) structural zeros (cover not bought -> 0); 7) prior-year claims history features known at renewal; 8) expected recoveries on open motor own-damage/theft; 9) developed-actual validation on 2 folds.
A20: Verification status | B20: Numbers quoted in Target_Assumptions come from the Oct 2026 profiling and the WENDY 3 model card. Treat them as approximate and re-check against the cleaning report after the next run.

Sheet Summary
A1: line | B1: peril | C1: freq features used | D1: sev features used | E1: sev_model | F1: cap_quantile | G1: rationale
A2: motor | B2: own_damage | C2: =COUNTIFS(Features_Motor!$G:$G,"Y",Features_Motor!J:J,"F")+COUNTIFS(Features_Motor!$G:$G,"Y",Features_Motor!J:J,"B") -> 38 | D2: =COUNTIFS(Features_Motor!$G:$G,"Y",Features_Motor!J:J,"S")+COUNTIFS(Features_Motor!$G:$G,"Y",Features_Motor!J:J,"B") -> 11 | E2: =Model_Spec!D2 -> gamma_gbm | F2: =Model_Spec!F2 -> 0.999 | G2: =Model_Spec!Q2 -> ~49k claims: data-rich, GBM for both parts.
A3: motor | B3: third_party_prop | C3: =COUNTIFS(Features_Motor!$G:$G,"Y",Features_Motor!K:K,"F")+COUNTIFS(Features_Motor!$G:$G,"Y",Features_Motor!K:K,"B") -> 33 | D3: =COUNTIFS(Features_Motor!$G:$G,"Y",Features_Motor!K:K,"S")+COUNTIFS(Features_Motor!$G:$G,"Y",Features_Motor!K:K,"B") -> 5 | E3: =Model_Spec!D3 -> gamma_gbm | F3: =Model_Spec!F3 -> 0.999 | G3: =Model_Spec!Q3 -> ~34k claims: data-rich.
A4: motor | B4: bodily_injury | C4: =COUNTIFS(Features_Motor!$G:$G,"Y",Features_Motor!L:L,"F")+COUNTIFS(Features_Motor!$G:$G,"Y",Features_Motor!L:L,"B") -> 17 | D4: =COUNTIFS(Features_Motor!$G:$G,"Y",Features_Motor!L:L,"S")+COUNTIFS(Features_Motor!$G:$G,"Y",Features_Motor!L:L,"B") -> 4 | E4: =Model_Spec!D4 -> gamma_glm | F4: =Model_Spec!F4 -> 0.995 | G4: =Model_Spec!Q4 -> ~7.6k claims, long tail (median report lag ~127 days), 2024 immature: Poisson GBM frequency + Gamma GLM severity on few factors; latest year left out of severity fit.
A5: motor | B5: theft | C5: =COUNTIFS(Features_Motor!$G:$G,"Y",Features_Motor!M:M,"F")+COUNTIFS(Features_Motor!$G:$G,"Y",Features_Motor!M:M,"B") -> 21 | D5: =COUNTIFS(Features_Motor!$G:$G,"Y",Features_Motor!M:M,"S")+COUNTIFS(Features_Motor!$G:$G,"Y",Features_Motor!M:M,"B") -> 9 | E5: =Model_Spec!D5 -> gamma_gbm | F5: =Model_Spec!F5 -> 0.999 | G5: =Model_Spec!Q5 -> ~6.5k claims; recoveries matter.
A6: motor | B6: glass_hail | C6: =COUNTIFS(Features_Motor!$G:$G,"Y",Features_Motor!N:N,"F")+COUNTIFS(Features_Motor!$G:$G,"Y",Features_Motor!N:N,"B") -> 16 | D6: =COUNTIFS(Features_Motor!$G:$G,"Y",Features_Motor!N:N,"S")+COUNTIFS(Features_Motor!$G:$G,"Y",Features_Motor!N:N,"B") -> 9 | E6: =Model_Spec!D6 -> gamma_gbm | F6: =Model_Spec!F6 -> 0.999 | G6: =Model_Spec!Q6 -> Weather-driven: no frequency trend.
A7: buildings | B7: storm | C7: =COUNTIFS(Features_Buildings!$G:$G,"Y",Features_Buildings!J:J,"F")+COUNTIFS(Features_Buildings!$G:$G,"Y",Features_Buildings!J:J,"B") -> 17 | D7: =COUNTIFS(Features_Buildings!$G:$G,"Y",Features_Buildings!J:J,"S")+COUNTIFS(Features_Buildings!$G:$G,"Y",Features_Buildings!J:J,"B") -> 11 | E7: =Model_Spec!D7 -> gamma_gbm | F7: =Model_Spec!F7 -> 0.999 | G7: =Model_Spec!Q7 -> ~7.8k claims; weather-driven.
A8: buildings | B8: flood | C8: =COUNTIFS(Features_Buildings!$G:$G,"Y",Features_Buildings!K:K,"F")+COUNTIFS(Features_Buildings!$G:$G,"Y",Features_Buildings!K:K,"B") -> 12 | D8: =COUNTIFS(Features_Buildings!$G:$G,"Y",Features_Buildings!K:K,"S")+COUNTIFS(Features_Buildings!$G:$G,"Y",Features_Buildings!K:K,"B") -> 10 | E8: =Model_Spec!D8 -> gamma_glm | F8: =Model_Spec!F8 -> 0.995 | G8: =Model_Spec!Q8 -> ~2.2k claims, strong hazard structure: GBM frequency, GLM severity.
A9: buildings | B9: escape_of_water | C9: =COUNTIFS(Features_Buildings!$G:$G,"Y",Features_Buildings!L:L,"F")+COUNTIFS(Features_Buildings!$G:$G,"Y",Features_Buildings!L:L,"B") -> 28 | D9: =COUNTIFS(Features_Buildings!$G:$G,"Y",Features_Buildings!L:L,"S")+COUNTIFS(Features_Buildings!$G:$G,"Y",Features_Buildings!L:L,"B") -> 10 | E9: =Model_Spec!D9 -> gamma_gbm | F9: =Model_Spec!F9 -> 0.999 | G9: =Model_Spec!Q9 -> ~10k claims: data-rich.
A10: buildings | B10: subsidence | C10: =COUNTIFS(Features_Buildings!$G:$G,"Y",Features_Buildings!M:M,"F")+COUNTIFS(Features_Buildings!$G:$G,"Y",Features_Buildings!M:M,"B") -> 14 | D10: =COUNTIFS(Features_Buildings!$G:$G,"Y",Features_Buildings!M:M,"S")+COUNTIFS(Features_Buildings!$G:$G,"Y",Features_Buildings!M:M,"B") -> 11 | E10: =Model_Spec!D10 -> gamma_glm | F10: =Model_Spec!F10 -> 0.995 | G10: =Model_Spec!Q10 -> ~1.3k claims, long tail (median lag ~94 days): GLM severity, latest year excluded from severity.
A11: buildings | B11: fire | C11: =COUNTIFS(Features_Buildings!$G:$G,"Y",Features_Buildings!N:N,"F")+COUNTIFS(Features_Buildings!$G:$G,"Y",Features_Buildings!N:N,"B") -> 19 | D11: =COUNTIFS(Features_Buildings!$G:$G,"Y",Features_Buildings!N:N,"S")+COUNTIFS(Features_Buildings!$G:$G,"Y",Features_Buildings!N:N,"B") -> 9 | E11: =Model_Spec!D11 -> gamma_glm | F11: =Model_Spec!F11 -> 0.99 | G11: =Model_Spec!Q11 -> ~1.1k claims, very heavy severity: GLM severity, lower cap.
A12: buildings | B12: accidental_damage | C12: =COUNTIFS(Features_Buildings!$G:$G,"Y",Features_Buildings!O:O,"F")+COUNTIFS(Features_Buildings!$G:$G,"Y",Features_Buildings!O:O,"B") -> 21 | D12: =COUNTIFS(Features_Buildings!$G:$G,"Y",Features_Buildings!O:O,"S")+COUNTIFS(Features_Buildings!$G:$G,"Y",Features_Buildings!O:O,"B") -> 5 | E12: =Model_Spec!D12 -> gamma_gbm | F12: =Model_Spec!F12 -> 0.999 | G12: =Model_Spec!Q12 -> ~3.8k claims; structural zero without AD cover.
A13: contents | B13: theft | C13: =COUNTIFS(Features_Contents!$G:$G,"Y",Features_Contents!J:J,"F")+COUNTIFS(Features_Contents!$G:$G,"Y",Features_Contents!J:J,"B") -> 25 | D13: =COUNTIFS(Features_Contents!$G:$G,"Y",Features_Contents!J:J,"S")+COUNTIFS(Features_Contents!$G:$G,"Y",Features_Contents!J:J,"B") -> 9 | E13: =Model_Spec!D13 -> gamma_gbm | F13: =Model_Spec!F13 -> 0.999 | G13: =Model_Spec!Q13 -> ~7.9k claims.
A14: contents | B14: escape_of_water | C14: =COUNTIFS(Features_Contents!$G:$G,"Y",Features_Contents!K:K,"F")+COUNTIFS(Features_Contents!$G:$G,"Y",Features_Contents!K:K,"B") -> 19 | D14: =COUNTIFS(Features_Contents!$G:$G,"Y",Features_Contents!K:K,"S")+COUNTIFS(Features_Contents!$G:$G,"Y",Features_Contents!K:K,"B") -> 8 | E14: =Model_Spec!D14 -> gamma_gbm | F14: =Model_Spec!F14 -> 0.999 | G14: =Model_Spec!Q14 -> ~5.4k claims.
A15: contents | B15: accidental_damage | C15: =COUNTIFS(Features_Contents!$G:$G,"Y",Features_Contents!L:L,"F")+COUNTIFS(Features_Contents!$G:$G,"Y",Features_Contents!L:L,"B") -> 21 | D15: =COUNTIFS(Features_Contents!$G:$G,"Y",Features_Contents!L:L,"S")+COUNTIFS(Features_Contents!$G:$G,"Y",Features_Contents!L:L,"B") -> 7 | E15: =Model_Spec!D15 -> gamma_gbm | F15: =Model_Spec!F15 -> 0.999 | G15: =Model_Spec!Q15 -> ~9.2k claims; structural zero without AD cover.
A16: contents | B16: flood | C16: =COUNTIFS(Features_Contents!$G:$G,"Y",Features_Contents!M:M,"F")+COUNTIFS(Features_Contents!$G:$G,"Y",Features_Contents!M:M,"B") -> 13 | D16: =COUNTIFS(Features_Contents!$G:$G,"Y",Features_Contents!M:M,"S")+COUNTIFS(Features_Contents!$G:$G,"Y",Features_Contents!M:M,"B") -> 10 | E16: =Model_Spec!D16 -> gamma_glm | F16: =Model_Spec!F16 -> 0.995 | G16: =Model_Spec!Q16 -> ~1.6k claims: GLM severity.
A18: Counts update when you change 'use' or peril codes in the Features sheets.

Sheet Target_Assumptions
A1: id | B1: topic | C1: question | D1: decision | E1: treatment in script | F1: evidence | G1: if done differently | H1: status
A2: 1 | B2: Recoveries | C2: Should recoveries be taken out? | D2: YES - keep deducting. The target is defined net of recoveries. | E2: claim cost = incurred_to_date - recoveries (as 2_clean). Open motor own_damage/theft claims have no recoveries booked yet, so expected recoveries are deducted: incurred x (closed recoveries / closed incurred) for that peril (setting open_claim_recovery_adjust). | F2: Recoveries appear only on CLOSED motor own_damage (~28.6% of claims) and theft (~12.0%); closed recoveries ~27.7M vs closed paid ~656.9M. | G2: Ignoring recoveries overstates motor cost; ignoring the open-claim gap overstates the immature 2024 year. | H2: Decided
A3: 2 | B3: Open claims | C3: Should claims that are not closed be taken out? | D3: NO - keep them at incurred (paid + case reserve). | E3: Open claims count in frequency and severity at incurred_to_date. | F3: Share open by loss year: 2021 0.9%, 2022 1.5%, 2023 3.2%, 2024 20.2%. Large/complex claims (bodily injury, subsidence) stay open longest. | G3: Dropping open claims removes ~20% of 2024 claims and is biased towards the largest ones -> severe under-prediction. | H3: Decided
A4: 3 | B4: Case development (IBNER) | C4: Will open case reserves move? | D4: Assume case reserves are adequate on average. | E4: No IBNER factor. Long-tail perils (bodily injury, subsidence) exclude the latest training year from the SEVERITY fit (Model_Spec sev_exclude_recent_years) so immature small claims do not bias severity down. | F4: Only one valuation date (31 Dec 2024) - development cannot be measured. | G4: Applying an untested factor adds error. | H4: Assumption - verify
A5: 4 | B5: Late reporting (IBNR) | C5: How to treat claims not yet reported? | D5: Model ULTIMATE frequency. | E5: Per peril, reported share = ECDF of report lags (2021-22 losses) at (31 Dec 2024 - row mid-date). Frequency volume = exposure x reported share. Validation actuals divided by the same share. | F5: 2024 IBNR count factor ~1.76 bodily injury, ~1.50 subsidence, ~1.02-1.06 others (WENDY 3). | G5: WENDY 3 multiplied targets by the factor -> scored against reported actuals -> unfair penalty. | H5: Decided
A6: 5 | B6: Repudiated claims | C6: Include declined claims? | D6: NO - excluded (cost 0, not counted). | E6: counts == TRUE only. | F6: ~1.0-1.1% of claims each year. | G6: - | H6: Decided
A7: 6 | B7: Excess | C7: Deduct the excess? | D7: NO - paid/incurred are already net of excess. | E7: Excess kept as a feature only. | F7: Data dictionary: paid_to_date is net of excess. | G7: Deducting again double-counts. | H7: Decided
A8: 7 | B8: Nil claims | C8: Non-repudiated claims with zero net cost? | D8: Excluded from frequency and severity. | E8: Frequency counts claims with net cost > 0, severity fitted on the same claims, so freq x sev = expected cost. | F8: Claims closed below the excess. | G8: Counting them in frequency but not severity overstates cost. | H8: Decided
A9: 8 | B9: Outlier claim | C9: The 11.9M open bodily-injury claim? | D9: Limit any single claim to 2,000,000 before capping (setting outlier_claim_limit). | E9: pmin(cost, limit). | F9: Paid ~0.74M; next largest claim ~1.12M closed. One claim = ~3.4% of all motor cost. | G9: Kept in full it adds ~7% to every bodily-injury prediction via the cap loading. | H9: Assumption - verify
A10: 9 | B10: Large-loss cap | C10: How to treat the tail? | D10: Cap each claim at a per-peril quantile; spread the excess as a loading. | E10: Model_Spec cap_quantile (0.99-0.999). Loading = trended total / trended capped total. | F10: Heavy tails: fire, flood, subsidence, bodily injury. | G10: Uncapped Gamma/Tweedie fits chase a few claims. | H10: Decided
A11: 10 | B11: Severity inflation | C11: Project severity to 2025? | D11: YES - log-linear trend per peril, clamped. | E11: Trend fitted on capped claim severity by loss year (excluding long-tail immature years); each claim trended to the prediction year (validation year or 2025). Clamp in Settings. | F11: Buildings severity ~8.7k (2021) -> ~10.3k (2024); contents ~2.7k -> ~2.9k. | G11: Without trend, 2025 is priced at the 2022-23 average. | H11: Decided
A12: 11 | B12: Frequency trend | C12: Project frequency? | D12: Only motor non-weather perils, residual-based, clamped. | E12: Model_Spec freq_trend = estimate: log(actual/expected) by year regressed on year after the GBM, so mix change is not counted as trend. | F12: Motor raw frequency 0.146 -> 0.140 (2021-23); weather perils vary with the year's weather, which is already a feature. | G12: Extrapolating weather years is noise. | H12: Assumption - verify
A13: 12 | B13: Unmatched claims | C13: Claims outside any policy row? | D13: Excluded. | E13: Rows with NA row_id dropped (2_clean). | F13: 414 claims; 252 dated exactly 2020-12-01 (placeholder). | G13: - | H13: Decided
... A25: 24 | B25: Validation | C25: How to compare models? | D25: 2 out-of-time folds against developed actuals; Tweedie D2 p = 1.5 (Kaggle metric). | E25: Selection per peril by mean D2 across folds (Settings model_selection = auto). | F25: WENDY 3 used one fold vs reported actuals. | G25: - | H25: Decided

Sheet Features_Motor
A1: column | B1: source | C1: type | D1: description | E1: actuarial_role | F1: decision | G1: use | H1: mono_freq | I1: mono_sev | J1: own_damage | K1: third_party_prop | L1: bodily_injury | M1: theft | N1: glass_hail | O1: reason | P1: guardrail
A2: driver_age_band | B2: policies_motor | C2: cat | D2: Main driver age at row start | E2: Driver risk | F2: Include | G2: Y | H2: 0 | I2: 0 | J2: B | K2: B | L2: B | M2: F | N2: - | O2: Core driver risk; also drives BI severity (vulnerability of occupants)
A3: years_licensed | B3: policies_motor | C3: num | D3: Years main driver licensed (capped at age-16) | E3: Driver experience | F3: Include | G3: Y | H3: 0 | I3: 0 | J3: F | K3: F | L3: F | M3: - | N3: - | O3: Driving experience separate from age
A4: ncb_years | B4: policies_motor | C4: num | D4: No-claims bonus years | E4: Claims history / experience | F4: Include | G4: Y | H4: -1 | I4: 0 | J4: F | K4: F | L4: F | M4: - | N4: - | O4: Strong frequency signal for at-fault perils; theft/glass are not at-fault
A5: vehicle_value_group | B5: policies_motor | C5: num | D5: Vehicle value band 1-20 | E5: Exposure to damage / theft severity | F5: Include | G5: Y | H5: 0 | I5: 1 | J5: B | K5: - | L5: - | M5: B | N5: B | O5: Damage, theft and glass cost scale with value; irrelevant to third-party liability
A6: vehicle_age | B6: policies_motor | C6: num | D6: Vehicle age | E6: Repair cost, theft attractiveness | F6: Include | G6: Y | H6: 0 | I6: 0 | J6: B | K6: F | L6: - | M6: B | N6: S | O6: Repair cost and theft target; glass cost
A7: make_model | B7: policies_motor | C7: cat | D7: Anonymised make/model code (high cardinality) | E7: Vehicle repair cost / theft target | F7: Test | G7: Y | H7: 0 | I7: 0 | J7: B | K7: F | L7: - | M7: B | N7: B | O7: Strong but high-cardinality; dropped for BI (spurious in WENDY 3) | P7: High cardinality - encoded by training rate order; overfit risk on sparse perils
A8: engine_size_cc | B8: policies_motor | C8: num | D8: Engine size | E8: Performance / driving style | F8: Include | G8: Y | H8: 0 | I8: 0 | J8: F | K8: B | L8: F | M8: F | N8: - | O8: Performance proxy
A9: body_type | B9: policies_motor | C9: cat | D9: Body type | E9: Repair cost, use pattern | F9: Include | G9: Y | H9: 0 | I9: 0 | J9: B | K9: B | L9: - | M9: F | N9: S | O9: Repair cost and use pattern
A10: transmission | B10: policies_motor | C10: cat | D10: Manual / automatic | E10: Weak driving-style proxy | F10: Test | G10: Y | H10: 0 | I10: 0 | J10: F | K10: - | L10: - | M10: - | N10: - | O10: Weak; own damage only
A11: seats | B11: policies_motor | C11: num | D11: Seats | E11: Occupants exposed to injury | F11: Test | G11: Y | H11: 0 | I11: 0 | J11: - | K11: - | L11: S | M11: - | N11: - | O11: More occupants -> larger BI claims
A12: vehicle_colour | B12: policies_motor | C12: cat | D12: Colour (~12.5% each, uniform) | E12: None - noise | F12: Exclude | G12: N | H12: 0 | I12: 0 | J12: - | K12: - | L12: - | M12: - | N12: - | O12: Uniform ~12.5% each; no causal path | P12: No causal path; uniform distribution suggests synthetic noise
A13: fuel_type | B13: policies_motor | C13: cat | D13: Petrol/diesel/hybrid/electric | E13: EV repair cost, theft target | F13: Test | G13: Y | H13: 0 | I13: 0 | J13: S | K13: - | L13: - | M13: F | N13: - | O13: EV/hybrid repair cost; theft targeting
A14: driver_assist | B14: policies_motor | C14: cat/bool | D14: Driver-assistance tech | E14: Collision avoidance | F14: Include | G14: Y | H14: 0 | I14: 0 | J14: F | K14: F | L14: F | M14: - | N14: - | O14: Collision avoidance reduces at-fault frequency
A15: cover_type | B15: policies_motor | C15: cat | D15: comprehensive / TPFT / TPO | E15: Defines which perils are covered (structural) | F15: Include | G15: Y | H15: 0 | I15: 0 | J15: B | K15: F | L15: F | M15: B | N15: B | O15: Defines cover; structural zeros applied for perils not covered | P15: Structural zeros enforced - see Structural_Zeros
A16: annual_mileage | B16: policies_motor | C16: num | D16: Declared mileage | E16: Exposure to road risk | F16: Include | G16: Y | H16: 1 | I16: 0 | J16: F | K16: F | L16: F | M16: - | N16: F | O16: Road exposure; more mileage -> more chips
A17: overnight_parking | B17: policies_motor | C17: cat | D17: Garage / driveway / street | E17: Theft, hail, vandalism | F17: Include | G17: Y | H17: 0 | I17: 0 | J17: F | K17: - | L17: - | M17: B | N17: F | O17: Theft and hail protection
A18: vehicle_use | B18: policies_motor | C18: cat | D18: Social / commuting / business | E18: Road exposure | F18: Include | G18: Y | H18: 0 | I18: 0 | J18: F | K18: F | L18: F | M18: - | N18: - | O18: Road exposure
A19: named_young_driver | B19: policies_motor | C19: bool | D19: Under-25 named driver | E19: Driver risk | F19: Include | G19: Y | H19: 1 | I19: 0 | J19: F | K19: F | L19: F | M19: - | N19: - | O19: Young driver risk
A20: telematics_opt_in | B20: policies_motor | C20: bool | D20: Telematics opt-in | E20: Self-selection signal | F20: Exclude | G20: N | H20: 0 | I20: 0 | J20: F | K20: F | L20: F | M20: - | N20: - | O20: Week 2: not shared by both markets or excluded. Self-selection of careful drivers
A21: telematics_score | B21: policies_motor | C21: num | D21: Score 1-100, NA if not opted in | E21: Observed driving behaviour | F21: Exclude | G21: N | H21: 0 | I21: 0 | J21: F | K21: F | L21: F | M21: - | N21: - | O21: Week 2: not shared by both markets or excluded. Observed behaviour; NA if not opted in (direction of scale not documented, so no constraint) | P21: NA by design; GBM handles NA natively
A22: voluntary_excess | B22: all policy files | C22: num | D22: Customer-chosen excess 0/250/500/1000 | E22: Removes small claims; self-selection | F22: Include | G22: Y | H22: -1 | I22: 0 | J22: B | K22: B | L22: B | M22: B | N22: B | O22: Removes small own-damage/theft/glass claims; BI not subject to excess (assumed) | P22: Claims already net of excess - do not subtract again
A23: compulsory_excess | B23: all policy files | C23: num | D23: Insurer-set excess | E23: Removes small claims | F23: Exclude | G23: N | H23: 0 | I23: 0 | J23: B | K23: - | L23: - | M23: B | N23: B | O23: Week 2: not shared by both markets or excluded. Same mechanism as voluntary excess
A24: channel | B24: all policy files | C24: cat | D24: direct / comparison / broker | E24: Selection effect | F24: Test | G24: Y | H24: 0 | I24: 0 | J24: F | K24: F | L24: - | M24: - | N24: - | O24: Selection effect by channel
A25: payment_method | B25: all policy files | C25: cat | D25: annual / monthly | E25: Financial-stress proxy | F25: Test | G25: Y | H25: 0 | I25: 0 | J25: F | K25: F | L25: - | M25: F | N25: - | O25: Financial-stress proxy | P25: Proxy factor - document in guardrails
A26: missed_payments_12m | B26: all policy files | C26: num | D26: Missed payments last 12m | E26: Financial-stress proxy | F26: Test | G26: Y | H26: 1 | I26: 0 | J26: F | K26: F | L26: - | M26: F | N26: - | O26: Financial-stress proxy | P26: Proxy factor - document in guardrails
A27: new_business | B27: all policy files | C27: bool | D27: First year with insurer | E27: Selection / unknown risk | F27: Test | G27: Y | H27: 0 | I27: 0 | J27: F | K27: F | L27: - | M27: - | N27: - | O27: New customers have unknown/higher risk
A28: renewal_count | B28: all policy files | C28: num | D28: Previous renewals | E28: Tenure / survivorship | F28: Test | G28: Y | H28: 0 | I28: 0 | J28: F | K28: F | L28: - | M28: - | N28: - | O28: Tenure; survivorship | P28: Survivorship bias: lapsed customers absent from test
A29: days_quote_to_inception | B29: all policy files | C29: num | D29: Days quote to start | E29: Anti-selection (last-minute buyers) | F29: Test | G29: Y | H29: 0 | I29: 0 | J29: F | K29: F | L29: - | M29: - | N29: - | O29: Last-minute buyers anti-selection
A30: discount_applied | B30: all policy files | C30: num | D30: Discount on price | E30: Commercial decision, not risk | F30: Exclude | G30: N | H30: 0 | I30: 0 | J30: - | K30: - | L30: - | M30: - | N30: - | O30: Commercial pricing decision, not risk | P30: Pricing decision - circular
A31: written_premium | B31: all policy files | C31: num | D31: Premium under current pricing | E31: Current price = old risk model + loadings | F31: Exclude | G31: N | H31: 0 | I31: 0 | J31: - | K31: - | L31: - | M31: - | N31: - | O31: Circular (current price); top gain in WENDY 3. Flip use to Y only as a documented challenger | P31: Circular for a technical price review; also embeds expense/profit loadings
A32: occupation | B32: customers | C32: cat | D32: Occupation | E32: Lifestyle / use | F32: Test | G32: Y | H32: 0 | I32: 0 | J32: F | K32: F | L32: - | M32: - | N32: - | O32: Lifestyle/use; guardrail review | P32: Potential proxy for protected traits - guardrail
A33: marital_status | B33: customers | C33: cat | D33: Marital status | E33: Driving behaviour proxy | F33: Test | G33: Y | H33: 0 | I33: 0 | J33: F | K33: F | L33: - | M33: - | N33: - | O33: Behaviour proxy; guardrail review | P33: Sensitive in some markets - guardrail
A34: household_size | B34: customers | C34: num | D34: People in household | E34: Occupancy, AD, EoW usage | F34: Exclude | G34: N | H34: 0 | I34: 0 | J34: - | K34: - | L34: - | M34: - | N34: - | O34: No clear motor mechanism
A35: credit_band | B35: customers | C35: cat | D35: Credit band A-E | E35: Financial-stress / claims propensity | F35: Exclude | G35: N | H35: 0 | I35: 0 | J35: F | K35: F | L35: - | M35: F | N35: - | O35: Week 2: not shared by both markets or excluded. Claims propensity; regulatory guardrail | P35: Credit-based insurance scoring restricted in some markets - guardrail
A36: prior_claims_5y | B36: customers | C36: num | D36: Declared claims 5y before joining | E36: Claims history | F36: Include | G36: Y | H36: 1 | I36: 0 | J36: F | K36: F | L36: F | M36: F | N36: F | O36: Declared history
A37: licence_points | B37: customers | C37: num | D37: Driving penalty points | E37: Driver conduct | F37: Include | G37: Y | H37: 1 | I37: 0 | J37: F | K37: F | L37: F | M37: - | N37: - | O37: Driver conduct
A38: years_at_address | B38: customers | C38: num | D38: Years at address | E38: Stability | F38: Test | G38: Y | H38: 0 | I38: 0 | J38: F | K38: - | L38: - | M38: F | N38: - | O38: Stability
A39: customer_since_year | B39: customers | C39: num | D39: First policy year | E39: Calendar cohort | F39: Exclude | G39: N | H39: 0 | I39: 0 | J39: - | K39: - | L39: - | M39: - | N39: - | O39: Cohort year; duplicates renewal_count | P39: Duplicates renewal_count; cohort year drifts out of range for 2025
A40: email_domain | B40: customers | C40: cat | D40: Anonymised email domain (~20% each) | E40: None - noise | F40: Exclude | G40: N | H40: 0 | I40: 0 | J40: - | K40: - | L40: - | M40: - | N40: - | O40: Noise | P40: Uniform; no causal path
...

Sheet Features_Buildings
A1: column | B1: source | C1: type | D1: description | E1: actuarial_role | F1: decision | G1: use | H1: mono_freq | I1: mono_sev | J1: storm | K1: flood | L1: escape_of_water | M1: subsidence | N1: fire | O1: accidental_damage | P1: reason | Q1: guardrail
A2: policyholder_age_band | B2: policies_buildings/contents | C2: cat | D2: Policyholder age | E2: Household behaviour | F2: Test | G2: Y | H2: 0 | I2: 0 | J2: - | K2: - | L2: F | M2: - | N2: F | O2: F | P2: Household behaviour | Q2: Age is a permitted factor in most markets; check local rules
A3: sum_insured | B3: policies_buildings/contents | C3: num | D3: Sum insured (1000x unit errors fixed in 2_clean) | E3: Severity scale / rebuild cost | F3: Include | G3: Y | H3: 0 | I3: 1 | J3: S | K3: S | L3: B | M3: S | N3: S | O3: S | P3: Severity scale; size also drives EoW frequency
A4: construction_type | B4: policies_buildings | C4: cat | D4: brick/stone/timber/non_standard (T,W -> timber) | E4: Fire, storm, subsidence vulnerability | F4: Include | G4: Y | H4: 0 | I4: 0 | J4: B | K4: - | L4: F | M4: B | N4: B | O4: - | P4: Timber/non-standard: fire, storm, subsidence vulnerability | Q4: T/W -> timber is an inference
A5: occupancy | B5: policies_buildings | C5: cat | D5: Owner occupied / let | E5: Moral hazard, maintenance | F5: Include | G5: Y | H5: 0 | I5: 0 | J5: - | K5: - | L5: F | M5: - | N5: F | O5: F | P5: Let properties: maintenance and moral hazard
A6: days_unoccupied | B6: policies_buildings | C6: num | D6: Longest period unoccupied | E6: Undetected leaks, fire | F6: Include | G6: Y | H6: 1 | I6: 0 | J6: - | K6: - | L6: B | M6: - | N6: F | O6: - | P6: Undetected leaks; arson/fire
A7: smoke_alarms | B7: policies_buildings | C7: bool | D7: Smoke alarms present | E7: Fire mitigation | F7: Include | G7: Y | H7: 0 | I7: 0 | J7: - | K7: - | L7: - | M7: - | N7: B | O7: - | P7: Fire detection reduces frequency and size
A8: accidental_damage_cover | B8: policies_buildings/contents | C8: bool | D8: Optional AD cover | E8: Defines whether AD is covered (structural) | F8: Include | G8: Y | H8: 0 | I8: 0 | J8: - | K8: - | L8: - | M8: - | N8: - | O8: B | P8: Structural for AD peril | Q8: Structural zero when not bought - see Structural_Zeros
A9: mortgage | B9: policies_buildings | C9: bool | D9: Mortgaged | E9: Financial proxy only | F9: Exclude | G9: N | H9: 0 | I9: 0 | J9: - | K9: - | L9: - | M9: - | N9: - | O9: - | P9: Financial proxy only | Q9: No direct causal path
A10: voluntary_excess | B10: all policy files | C10: num | D10: Customer-chosen excess 0/250/500/1000 | E10: Removes small claims; self-selection | F10: Include | G10: Y | H10: -1 | I10: 0 | J10: B | K10: B | L10: B | M10: B | N10: B | O10: B | P10: Removes small claims; behaviour | Q10: Claims already net of excess - do not subtract again
A11: compulsory_excess | B11: all policy files | C11: num | D11: Insurer-set excess | E11: Removes small claims | F11: Exclude | G11: N | H11: 0 | I11: 0 | J11: S | K11: S | L11: S | M11: S | N11: S | O11: S | P11: Week 2: not shared by both markets or excluded. Applied per claim
A12: channel | B12: all policy files | C12: cat | D12: direct / comparison / broker | E12: Selection effect | F12: Test | G12: Y | H12: 0 | I12: 0 | J12: F | K12: - | L12: F | M12: - | N12: - | O12: F | P12: Selection
A13: payment_method | B13: all policy files | C13: cat | D13: annual / monthly | E13: Financial-stress proxy | F13: Test | G13: Y | H13: 0 | I13: 0 | J13: - | K13: - | L13: F | M13: - | N13: - | O13: F | P13: Financial-stress proxy (maintenance) | Q13: Proxy factor - document in guardrails
A14: missed_payments_12m | B14: all policy files | C14: num | D14: Missed payments last 12m | E14: Financial-stress proxy | F14: Test | G14: Y | H14: 1 | I14: 0 | J14: - | K14: - | L14: F | M14: - | N14: F | O14: F | P14: Financial-stress proxy | Q14: Proxy factor - document in guardrails
A15: new_business | B15: all policy files | C15: bool | D15: First year with insurer | E15: Selection / unknown risk | F15: Test | G15: Y | H15: 0 | I15: 0 | J15: - | K15: - | L15: F | M15: - | N15: - | O15: F | P15: Selection
A16: renewal_count | B16: all policy files | C16: num | D16: Previous renewals | E16: Tenure / survivorship | F16: Test | G16: Y | H16: 0 | I16: 0 | J16: - | K16: - | L16: F | M16: - | N16: - | O16: F | P16: Tenure | Q16: Survivorship bias: lapsed customers absent from test
A17: days_quote_to_inception | B17: all policy files | C17: num | D17: Days quote to start | E17: Anti-selection (last-minute buyers) | F17: Test | G17: Y | H17: 0 | I17: 0 | J17: F | K17: - | L17: F | M17: - | N17: - | O17: F | P17: Anti-selection (e.g. buying ahead of forecast storms)
A18: discount_applied | B18: all policy files | C18: num | D18: Discount on price | E18: Commercial decision, not risk | F18: Exclude | G18: N | H18: 0 | I18: 0 | J18: - | K18: - | L18: - | M18: - | N18: - | O18: - | P18: Commercial | Q18: Pricing decision - circular
A19: written_premium | B19: all policy files | C19: num | D19: Premium under current pricing | E19: Current price = old risk model + loadings | F19: Exclude | G19: N | H19: 0 | I19: 0 | J19: - | K19: - | L19: - | M19: - | N19: - | O19: - | P19: Circular; was top gain for flood in WENDY 3 - flood hazard now from flood_zone/elevation directly | Q19: Circular for a technical price review; also embeds expense/profit loadings
A20: occupation | B20: customers | C20: cat | D20: Occupation | E20: Lifestyle / use | F20: Exclude | G20: N | H20: 0 | I20: 0 | J20: - | K20: - | L20: - | M20: - | N20: - | O20: - | P20: Spurious in sparse perils | Q20: Potential proxy for protected traits - guardrail
A21: marital_status | B21: customers | C21: cat | D21: Marital status | E21: Driving behaviour proxy | F21: Exclude | G21: N | H21: 0 | I21: 0 | J21: - | K21: - | L21: - | M21: - | N21: - | O21: - | P21: No home mechanism | Q21: Sensitive in some markets - guardrail
A22: household_size | B22: customers | C22: num | D22: People in household | E22: Occupancy, AD, EoW usage | F22: Test | G22: Y | H22: 0 | I22: 0 | J22: - | K22: - | L22: F | M22: - | N22: F | O22: F | P22: Water usage, cooking fires, AD
A23: credit_band | B23: customers | C23: cat | D23: Credit band A-E | E23: Financial-stress / claims propensity | F23: Exclude | G23: N | H23: 0 | I23: 0 | J23: - | K23: - | L23: F | M23: - | N23: F | O23: F | P23: Week 2: not shared by both markets or excluded. Maintenance proxy; guardrail | Q23: Credit-based insurance scoring restricted in some markets - guardrail
A24: prior_claims_5y | B24: customers | C24: num | D24: Declared claims 5y before joining | E24: Claims history | F24: Include | G24: Y | H24: 1 | I24: 0 | J24: F | K24: F | L24: F | M24: F | N24: F | O24: F | P24: Declared history
A25: licence_points | B25: customers | C25: num | D25: Driving penalty points | E25: Driver conduct | F25: Exclude | G25: N | H25: 0 | I25: 0 | J25: - | K25: - | L25: - | M25: - | N25: - | O25: - | P25: Motor conduct, not home
A26: years_at_address | B26: customers | C26: num | D26: Years at address | E26: Stability | F26: Test | G26: Y | H26: 0 | I26: 0 | J26: - | K26: - | L26: F | M26: - | N26: - | O26: F | P26: Stability
A27: customer_since_year | B27: customers | C27: num | D27: First policy year | E27: Calendar cohort | F27: Exclude | G27: N | H27: 0 | I27: 0 | J27: - | K27: - | L27: - | M27: - | N27: - | O27: - | P27: Cohort year | Q27: Duplicates renewal_count; cohort year drifts out of range for 2025
A28: email_domain | B28: customers | C28: cat | D28: Anonymised email domain (~20% each) | E28: None - noise | F28: Exclude | G28: N | H28: 0 | I28: 0 | J28: - | K28: - | L28: - | M28: - | N28: - | O28: - | P28: Noise | Q28: Uniform; no causal path
A29: marketing_consent | B29: customers | C29: bool | D29: Marketing consent | E29: None | F29: Exclude | G29: N | H29: 0 | I29: 0 | J29: - | K29: - | L29: - | M29: - | N29: - | O29: - | P29: No causal path | Q29: No causal path
A30: document_preference | B30: customers | C30: cat | D30: email / post / app | E30: None (age proxy at best) | F30: Exclude | G30: N | H30: 0 | I30: 0 | J30: - | K30: - | L30: - | M30: - | N30: - | O30: - | P30: No causal path | Q30: Proxy only
A31: previous_insurer | B31: customers | C31: cat | D31: Previous insurer | E31: Weak selection signal | F31: Exclude | G31: N | H31: 0 | I31: 0 | J31: - | K31: - | L31: - | M31: - | N31: - | O31: - | P31: Spurious for fire/subsidence in WENDY 3 | Q31: Showed spurious top-10 importance for fire / subsidence in WENDY 3
A32: campaign_code | B32: customers | C32: cat | D32: Acquisition campaign | E32: Marketing | F32: Exclude | G32: N | H32: 0 | I32: 0 | J32: - | K32: - | L32: - | M32: - | N32: - | O32: - | P32: Spurious for subsidence in WENDY 3 | Q32: No causal path; null = no campaign
A33: branch_id | B33: customers | C33: cat | D33: Servicing branch | E33: Geography proxy (region already used) | F33: Exclude | G33: N | H33: 0 | I33: 0 | J33: - | K33: - | L33: - | M33: - | N33: - | O33: - | P33: Duplicates geography | Q33: Duplicates geography
A34: marketing_segment | B34: customers | C34: cat | D34: Marketing segment | E34: Opaque derived score | F34: Exclude | G34: N | H34: 0 | I34: 0 | J34: - | K34: - | L34: - | M34: - | N34: - | O34: - | P34: Opaque | Q34: Unknown construction - could encode price or protected traits
A35: region | B35: addresses | C35: cat | D35: Region R01-R12 | E35: Geography | F35: Exclude | G35: N | H35: 0 | I35: 0 | J35: B | K35: B | L35: B | M35: B | N35: B | O35: B | P35: Week 2: not shared by both markets or excluded. Geography, rebuild cost
A36: urban_density | B36: addresses | C36: cat | D36: rural ... dense_urban | E36: Traffic, crime density | F36: Test | G36: Y | H36: 0 | I36: 0 | J36: F | K36: - | L36: F | M36: - | N36: F | O36: F | P36: Arson, density
A37: flood_zone | B37: addresses | C37: num | D37: Flood zone 1-5 | E37: Flood hazard | F37: Include | G37: Y | H37: 1 | I37: 0 | J37: - | K37: B | L37: - | M37: - | N37: - | O37: - | P37: Flood hazard
A38: distance_to_river_km | B38: addresses | C38: num | D38: Distance to river | E38: Flood hazard | F38: Include | G38: Y | H38: -1 | I38: 0 | J38: - | K38: B | L38: - | M38: - | N38: - | O38: - | P38: Flood hazard
A39: elevation_m | B39: addresses | C39: num | D39: Height above river level | E39: Flood hazard | F39: Include | G39: Y | H39: -1 | I39: 0 | J39: - | K39: B | L39: - | M39: - | N39: - | O39: - | P39: Flood hazard
A40: soil_type | B40: addresses | C40: cat | D40: clay/sand/loam/chalk/rock | E40: Subsidence hazard (clay shrink-swell) | F40: Include | G40: Y | H40: 0 | I40: 0 | J40: - | K40: - | L40: - | M40: B | N40: - | O40: - | P40: Clay shrink-swell
...

Sheet Features_Contents
A1: column | B1: source | C1: type | D1: description | E1: actuarial_role | F1: decision | G1: use | H1: mono_freq | I1: mono_sev | J1: theft | K1: escape_of_water | L1: accidental_damage | M1: flood | N1: reason | O1: guardrail
A2: policyholder_age_band | B2: policies_buildings/contents | C2: cat | D2: Policyholder age | E2: Household behaviour | F2: Test | G2: Y | H2: 0 | I2: 0 | J2: F | K2: - | L2: F | M2: - | N2: Household behaviour | O2: Age is a permitted factor in most markets; check local rules
A3: sum_insured | B3: policies_buildings/contents | C3: num | D3: Sum insured (1000x unit errors fixed in 2_clean) | E3: Severity scale / rebuild cost | F3: Include | G3: Y | H3: 0 | I3: 1 | J3: B | K3: S | L3: B | M3: S | N3: Severity scale; more contents more theft/AD
A4: accidental_damage_cover | B4: policies_buildings/contents | C4: bool | D4: Optional AD cover | E4: Defines whether AD is covered (structural) | F4: Include | G4: Y | H4: 0 | I4: 0 | J4: - | K4: - | L4: B | M4: - | N4: Structural for AD peril | O4: Structural zero when not bought - see Structural_Zeros
A5: tenure | B5: policies_contents | C5: cat | D5: Owner / renter | E5: Theft, EoW exposure | F5: Include | G5: Y | H5: 0 | I5: 0 | J5: F | K5: F | L5: F | M5: F | N5: Renters: different exposure
A6: security_level | B6: policies_contents | C6: cat | D6: standard / locks / alarm_and_locks | E6: Theft mitigation | F6: Include | G6: Y | H6: 0 | I6: 0 | J6: B | K6: - | L6: - | M6: - | N6: Theft mitigation
A7: high_value_items | B7: policies_contents | C7: num | D7: Declared high-value items | E7: Theft attractiveness, severity | F7: Include | G7: Y | H7: 1 | I7: 0 | J7: B | K7: - | L7: S | M7: - | N7: Theft attractiveness and size
A8: works_from_home | B8: policies_contents | C8: bool | D8: Someone works from home | E8: Daytime occupancy (theft), AD | F8: Test | G8: Y | H8: 0 | I8: 0 | J8: F | K8: F | L8: F | M8: - | N8: Daytime occupancy
A9: lodgers | B9: policies_contents | C9: bool | D9: Lodgers/students in household | E9: Theft, AD | F9: Test | G9: Y | H9: 0 | I9: 0 | J9: F | K9: - | L9: F | M9: - | N9: Theft/AD by occupants
A10: bicycle_cover | B10: policies_contents | C10: bool | D10: Optional bicycle cover | E10: Adds bicycle theft exposure | F10: Include | G10: Y | H10: 0 | I10: 0 | J10: B | K10: - | L10: - | M10: - | N10: Adds bicycle theft exposure
A11: voluntary_excess | B11: all policy files | C11: num | D11: Customer-chosen excess 0/250/500/1000 | E11: Removes small claims; self-selection | F11: Include | G11: Y | H11: -1 | I11: 0 | J11: B | K11: B | L11: B | M11: B | N11: Removes small claims | O11: Claims already net of excess - do not subtract again
A12: compulsory_excess | B12: all policy files | C12: num | D12: Insurer-set excess | E12: Removes small claims | F12: Exclude | G12: N | H12: 0 | I12: 0 | J12: S | K12: S | L12: S | M12: S | N12: Week 2: not shared by both markets or excluded. Applied per claim
A13: channel | B13: all policy files | C13: cat | D13: direct / comparison / broker | E13: Selection effect | F13: Test | G13: Y | H13: 0 | I13: 0 | J13: F | K13: - | L13: F | M13: - | N13: Selection
A14: payment_method | B14: all policy files | C14: cat | D14: annual / monthly | E14: Financial-stress proxy | F14: Test | G14: Y | H14: 0 | I14: 0 | J14: F | K14: - | L14: F | M14: - | N14: Financial-stress proxy | O14: Proxy factor - document in guardrails
A15: missed_payments_12m | B15: all policy files | C15: num | D15: Missed payments last 12m | E15: Financial-stress proxy | F15: Test | G15: Y | H15: 1 | I15: 0 | J15: F | K15: - | L15: F | M15: - | N15: Financial-stress proxy | O15: Proxy factor - document in guardrails
A16: new_business | B16: all policy files | C16: bool | D16: First year with insurer | E16: Selection / unknown risk | F16: Test | G16: Y | H16: 0 | I16: 0 | J16: F | K16: F | L16: F | M16: - | N16: Selection
A17: renewal_count | B17: all policy files | C17: num | D17: Previous renewals | E17: Tenure / survivorship | F17: Test | G17: Y | H17: 0 | I17: 0 | J17: F | K17: F | L17: F | M17: - | N17: Tenure | O17: Survivorship bias: lapsed customers absent from test
A18: days_quote_to_inception | B18: all policy files | C18: num | D18: Days quote to start | E18: Anti-selection (last-minute buyers) | F18: Test | G18: Y | H18: 0 | I18: 0 | J18: F | K18: - | L18: F | M18: F | N18: Anti-selection
A19: discount_applied | B19: all policy files | C19: num | D19: Discount on price | E19: Commercial decision, not risk | F19: Exclude | G19: N | H19: 0 | I19: 0 | J19: - | K19: - | L19: - | M19: - | N19: Commercial | O19: Pricing decision - circular
A20: written_premium | B20: all policy files | C20: num | D20: Premium under current pricing | E20: Current price = old risk model + loadings | F20: Exclude | G20: N | H20: 0 | I20: 0 | J20: - | K20: - | L20: - | M20: - | N20: Circular; top gain for theft/EoW in WENDY 3 | O20: Circular for a technical price review; also embeds expense/profit loadings
A21: occupation | B21: customers | C21: cat | D21: Occupation | E21: Lifestyle / use | F21: Exclude | G21: N | H21: 0 | I21: 0 | J21: - | K21: - | L21: - | M21: - | N21: Proxy; not needed | O21: Potential proxy for protected traits - guardrail
A22: marital_status | B22: customers | C22: cat | D22: Marital status | E22: Driving behaviour proxy | F22: Exclude | G22: N | H22: 0 | I22: 0 | J22: - | K22: - | L22: - | M22: - | N22: No mechanism | O22: Sensitive in some markets - guardrail
A23: household_size | B23: customers | C23: num | D23: People in household | E23: Occupancy, AD, EoW usage | F23: Test | G23: Y | H23: 0 | I23: 0 | J23: F | K23: F | L23: F | M23: - | N23: Occupants
A24: credit_band | B24: customers | C24: cat | D24: Credit band A-E | E24: Financial-stress / claims propensity | F24: Exclude | G24: N | H24: 0 | I24: 0 | J24: F | K24: F | L24: F | M24: - | N24: Week 2: not shared by both markets or excluded. Claims propensity; guardrail | O24: Credit-based insurance scoring restricted in some markets - guardrail
A25: prior_claims_5y | B25: customers | C25: num | D25: Declared claims 5y before joining | E25: Claims history | F25: Include | G25: Y | H25: 1 | I25: 0 | J25: F | K25: F | L25: F | M25: F | N25: Declared history
A26: licence_points | B26: customers | C26: num | D26: Driving penalty points | E26: Driver conduct | F26: Exclude | G26: N | H26: 0 | I26: 0 | J26: - | K26: - | L26: - | M26: - | N26: Motor conduct
A27: years_at_address | B27: customers | C27: num | D27: Years at address | E27: Stability | F27: Test | G27: Y | H27: 0 | I27: 0 | J27: F | K27: F | L27: - | M27: - | N27: Stability
A28: customer_since_year | B28: customers | C28: num | D28: First policy year | E28: Calendar cohort | F28: Exclude | G28: N | H28: 0 | I28: 0 | J28: - | K28: - | L28: - | M28: - | N28: Cohort year | O28: Duplicates renewal_count; cohort year drifts out of range for 2025
A29: email_domain | B29: customers | C29: cat | D29: Anonymised email domain (~20% each) | E29: None - noise | F29: Exclude | G29: N | H29: 0 | I29: 0 | J29: - | K29: - | L29: - | M29: - | N29: Noise | O29: Uniform; no causal path
A30: marketing_consent | B30: customers | C30: bool | D30: Marketing consent | E30: None | F30: Exclude | G30: N | H30: 0 | I30: 0 | J30: - | K30: - | L30: - | M30: - | N30: No causal path | O30: No causal path
A31: document_preference | B31: customers | C31: cat | D31: email / post / app | E31: None (age proxy at best) | F31: Exclude | G31: N | H31: 0 | I31: 0 | J31: - | K31: - | L31: - | M31: - | N31: No causal path | O31: Proxy only
A32: previous_insurer | B32: customers | C32: cat | D32: Previous insurer | E32: Weak selection signal | F32: Exclude | G32: N | H32: 0 | I32: 0 | J32: - | K32: - | L32: - | M32: - | N32: No mechanism | O32: Showed spurious top-10 importance for fire / subsidence in WENDY 3
A33: campaign_code | B33: customers | C33: cat | D33: Acquisition campaign | E33: Marketing | F33: Exclude | G33: N | H33: 0 | I33: 0 | J33: - | K33: - | L33: - | M33: - | N33: Marketing | O33: No causal path; null = no campaign
A34: branch_id | B34: customers | C34: cat | D34: Servicing branch | E34: Geography proxy (region already used) | F34: Exclude | G34: N | H34: 0 | I34: 0 | J34: - | K34: - | L34: - | M34: - | N34: Duplicates geography | O34: Duplicates geography
A35: marketing_segment | B35: customers | C35: cat | D35: Marketing segment | E35: Opaque derived score | F35: Exclude | G35: N | H35: 0 | I35: 0 | J35: - | K35: - | L35: - | M35: - | N35: Opaque; ranked high for theft/EoW in WENDY 3 without a mechanism | O35: Unknown construction - could encode price or protected traits
A36: region | B36: addresses | C36: cat | D36: Region R01-R12 | E36: Geography | F36: Exclude | G36: N | H36: 0 | I36: 0 | J36: B | K36: B | L36: B | M36: B | N36: Week 2: not shared by both markets or excluded. Geography
A37: urban_density | B37: addresses | C37: cat | D37: rural ... dense_urban | E37: Traffic, crime density | F37: Include | G37: Y | H37: 0 | I37: 0 | J37: B | K37: - | L37: F | M37: - | N37: Crime density
A38: flood_zone | B38: addresses | C38: num | D38: Flood zone 1-5 | E38: Flood hazard | F38: Include | G38: Y | H38: 1 | I38: 0 | J38: - | K38: - | L38: - | M38: B | N38: Flood hazard
A39: distance_to_river_km | B39: addresses | C39: num | D39: Distance to river | E39: Flood hazard | F39: Include | G39: Y | H39: -1 | I39: 0 | J39: - | K39: - | L39: - | M39: B | N39: Flood hazard
A40: elevation_m | B40: addresses | C40: num | D40: Height above river level | E40: Flood hazard | F40: Include | G40: Y | H40: -1 | I40: 0 | J40: - | K40: - | L40: - | M40: B | N40: Flood hazard
...

Sheet Model_Spec
A1: line | B1: peril | C1: freq_model | D1: sev_model | E1: challenger_tweedie | F1: cap_quantile | G1: sev_trend | H1: freq_trend | I1: sev_exclude_recent_years | J1: freq_max_depth | K1: freq_eta | L1: freq_min_child_weight | M1: sev_max_depth | N1: sev_eta | O1: sev_min_child_weight | P1: tweedie_p | Q1: rationale
A2: motor | B2: own_damage | C2: poisson_gbm | D2: gamma_gbm | E2: Y | F2: 0.999 | G2: estimate | H2: estimate | I2: 0 | J2: 4 | K2: 0.05 | L2: 50 | M2: 3 | N2: 0.05 | O2: 100 | P2: 1.5 | Q2: ~49k claims: data-rich, GBM for both parts.
A3: motor | B3: third_party_prop | C3: poisson_gbm | D3: gamma_gbm | E3: Y | F3: 0.999 | G3: estimate | H3: estimate | I3: 0 | J3: 4 | K3: 0.05 | L3: 50 | M3: 3 | N3: 0.05 | O3: 100 | P3: 1.5 | Q3: ~34k claims: data-rich.
A4: motor | B4: bodily_injury | C4: poisson_gbm | D4: gamma_glm | E4: Y | F4: 0.995 | G4: none | H4: none | I4: 1 | J4: 3 | K4: 0.05 | L4: 100 | M4: 0 | N4: 0 | O4: 0 | P4: 1.6 | Q4: ~7.6k claims, long tail (median report lag ~127 days), 2024 immature: Poisson GBM frequency + Gamma GLM severity on few factors; latest year left out of severity fit.
A5: motor | B5: theft | C5: poisson_gbm | D5: gamma_glm | E5: Y | F5: 0.999 | G5: estimate | H5: none | I5: 0 | J5: 3 | K5: 0.05 | L5: 50 | M5: 3 | N5: 0.05 | O5: 100 | P5: 1.5 | Q5: ~6.5k claims; recoveries matter.
A6: motor | B6: glass_hail | C6: poisson_gbm | D6: gamma_gbm | E6: Y | F6: 0.999 | G6: estimate | H6: none | I6: 0 | J6: 3 | K6: 0.05 | L6: 50 | M6: 3 | N6: 0.05 | O6: 100 | P6: 1.5 | Q6: Weather-driven: no frequency trend.
A7: buildings | B7: storm | C7: poisson_gbm | D7: gamma_gbm | E7: Y | F7: 0.999 | G7: estimate | H7: none | I7: 0 | J7: 3 | K7: 0.05 | L7: 50 | M7: 3 | N7: 0.05 | O7: 100 | P7: 1.5 | Q7: ~7.8k claims; weather-driven.
A8: buildings | B8: flood | C8: poisson_gbm | D8: gamma_glm | E8: Y | F8: 0.995 | G8: estimate | H8: none | I8: 0 | J8: 3 | K8: 0.05 | L8: 30 | M8: 0 | N8: 0 | O8: 0 | P8: 1.6 | Q8: ~2.2k claims, strong hazard structure: GBM frequency, GLM severity.
A9: buildings | B9: escape_of_water | C9: poisson_gbm | D9: gamma_glm | E9: Y | F9: 0.999 | G9: estimate | H9: none | I9: 0 | J9: 4 | K9: 0.05 | L9: 50 | M9: 3 | N9: 0.05 | O9: 100 | P9: 1.5 | Q9: ~10k claims: data-rich.
A10: buildings | B10: subsidence | C10: poisson_gbm | D10: gamma_glm | E10: Y | F10: 0.995 | G10: estimate | H10: none | I10: 1 | J10: 3 | K10: 0.05 | L10: 30 | M10: 0 | N10: 0 | O10: 0 | P10: 1.6 | Q10: ~1.3k claims, long tail (median lag ~94 days): GLM severity, latest year excluded from severity.
A11: buildings | B11: fire | C11: poisson_gbm | D11: gamma_glm | E11: Y | F11: 0.99 | G11: estimate | H11: none | I11: 0 | J11: 3 | K11: 0.05 | L11: 15 | M11: 0 | N11: 0 | O11: 0 | P11: 1.7 | Q11: ~1.1k claims, very heavy severity: GLM severity, lower cap.
A12: buildings | B12: accidental_damage | C12: poisson_gbm | D12: gamma_gbm | E12: Y | F12: 0.999 | G12: estimate | H12: none | I12: 0 | J12: 3 | K12: 0.05 | L12: 30 | M12: 3 | N12: 0.05 | O12: 100 | P12: 1.5 | Q12: ~3.8k claims; structural zero without AD cover.
A13: contents | B13: theft | C13: poisson_gbm | D13: gamma_glm | E13: Y | F13: 0.999 | G13: estimate | H13: none | I13: 0 | J13: 4 | K13: 0.05 | L13: 50 | M13: 3 | N13: 0.05 | O13: 100 | P13: 1.5 | Q13: ~7.9k claims.
... A16: contents | B16: flood | C16: poisson_gbm | D16: gamma_glm | E16: Y | F16: 0.995 | G16: estimate | H16: none | I16: 0 | J16: 3 | K16: 0.05 | L16: 30 | M16: 0 | N16: 0 | O16: 0 | P16: 1.6 | Q16: ~1.6k claims: GLM severity.
A18: Notes
A19: freq_min_child_weight ~ minimum expected claim count per leaf (Poisson hessian ~ expected count; xgboost's max_delta_step inflates it roughly 2x - approximate).
A20: sev_min_child_weight ~ minimum claims per leaf for the Gamma GBM. sev_* depth/eta are ignored when sev_model = gamma_glm.
A21: sev_trend / freq_trend: estimate = fit inside each training window and clamp to the Settings bounds; none = no trend.
A22: cap_quantile is taken over that peril's positive claim costs in the training window (after the outlier limit and trend).

Sheet Structural_Zeros
A1: line | B1: peril | C1: column | D1: values | E1: rationale
A2: motor | B2: own_damage | C2: cover_type | D2: third_party_only,third_party_fire_theft | E2: Own damage is only covered by comprehensive.
A3: motor | B3: glass_hail | C3: cover_type | D3: third_party_only,third_party_fire_theft | E3: Glass is normally a comprehensive benefit (assumption - the data check decides).
A4: motor | B4: theft | C4: cover_type | D4: third_party_only | E4: Theft is covered by TPFT and comprehensive only.
A5: buildings | B5: accidental_damage | C5: accidental_damage_cover | D5: FALSE | E5: AD only covered if bought.
A6: contents | B6: accidental_damage | C6: accidental_damage_cover | D6: FALSE | E6: AD only covered if bought.
A8: A rule is applied only if the training data has ZERO positive claims of that peril in those rows; otherwise the script warns and ignores it. Values are matched case-insensitively against the column as text.

Sheet Settings
A1: key | B1: value | C1: note
A2: valid_years | B2: 2023,2024 | C2: Out-of-time folds: each is fitted on all earlier years.
A3: target_year | B3: 2025 | C3: Year the submission predicts (trend target).
A4: lag_loss_years | B4: 2021,2022 | C4: Loss years whose report lags define the reporting pattern.
A5: outlier_claim_limit | B5: 2000000 | C5: Single-claim limit applied before caps (CU).
A6: sev_trend_min | B6: -0.02 | C6: Lower clamp on annual severity trend.
A7: sev_trend_max | B7: 0.10 | C7: Upper clamp on annual severity trend.
A8: freq_trend_min | B8: -0.05 | C8: Lower clamp on annual frequency trend.
A9: freq_trend_max | B9: 0.03 | C9: Upper clamp on annual frequency trend.
A10: model_selection | B10: freq_sev | C10: auto = better of freq_sev / tweedie per peril by mean validation D2; freq_sev or tweedie forces one.
A11: open_claim_recovery_adjust | B11: Y | C11: Deduct expected recoveries from OPEN claims of perils with recoveries (closed recovery ratio).
A12: history_features | B12: Y | C12: Build hist_* prior-year claims features (Y/N).
A13: max_rounds | B13: 3000 | C13: Max boosting rounds (early stopping decides).
A14: early_stopping_rounds | B14: 50
A15: holdout_share | B15: 0.10 | C15: Share of training POLICIES held out for early stopping.
A16: subsample | B16: 0.8 | C16: Row subsample per tree.
A17: colsample_bytree | B17: 0.8 | C17: Feature subsample per tree.
A18: reg_lambda | B18: 5 | C18: L2 regularisation.
A19: glm_min_level_claims | B19: 30 | C19: GLM severity: category levels with fewer claims are pooled into 'other'.
A20: glm_log_features | B20: sum_insured,annual_mileage,distance_to_river_km | C20: Numeric features entered as log(1+x) in GLM severity.
A21: score_tweedie_p | B21: 1.5 | C21: Power of the Tweedie D2 metric (Kaggle).
A22: nthread | B22: 0 | C22: 0 = all cores.
A23: ibnr_method | B23: chain_ladder | C23: WENDY 7: reported-count chain ladder per peril (loss quarter x development quarter, 2021-24 losses).
A24: ibnr_override | B24: buildings/subsidence=report_share_days | C24: Per-peril IBNR method: subsidence uses the lag ECDF averaged over the row's days (sparse triangle).
A25: bags | B25: 1 | C25: WENDY 7: each xgboost component = mean of 5 boosters (own policy holdout, seed SEED + b); bag 1 = WENDY 4 fit.
A26: method_mix | B26: auto | C26: WENDY 7: freq_sev / tweedie per peril read from sheet Method_Mix (environment METHOD_MIX overrides).

Sheet Column_Register
A1: column | B1: source | C1: description | D1: actuarial_role | E1: motor | F1: buildings | G1: contents | H1: guardrail
A2: row_id | B2: all policy files | C2: Row key | D2: Identifier | E2: n/a | F2: n/a | G2: n/a | H2: Identifier - excluded
A3: policy_id | B3: all policy files | C3: Policy key (constant across years) | D3: Identifier; used to build history and holdouts | E3: n/a | F3: n/a | G3: n/a | H3: Identifier - excluded
A4: customer_id | B4: all policy files | C4: Customer key (leading zeros fixed) | D4: Identifier; used for cross-line history | E4: n/a | F4: n/a | G4: n/a | H4: Identifier - excluded
A5: address_id | B5: all policy files | C5: Address key | D5: Join key to addresses/weather | E5: n/a | F5: n/a | G5: n/a | H5: Identifier - excluded
A6: period_start / period_end | B6: all policy files | C6: Cover dates | D6: Exposure, IBNR share, start_month | E6: n/a | F6: n/a | G6: n/a | H6: Raw dates excluded
A7: exposure | B7: all policy files | C7: Years on cover (recomputed) | D7: Frequency volume | E7: n/a | F7: n/a | G7: n/a | H7: Volume, not a feature
A8: renewal_decision | B8: train only | C8: Row outcome | D8: LEAKAGE | E8: n/a | F8: n/a | G8: n/a | H8: Dropped in 2_clean
A9: customer_service_contacts | B9: all policy files | C9: Service contacts | D9: LEAKAGE | E9: n/a | F9: n/a | G9: n/a | H9: Excluded in 0_setup
A10: surname | B10: customers | C10: Anonymised surname | D10: None | E10: n/a | F10: n/a | G10: n/a | H10: Dropped (possible ethnicity proxy)
A11: date_of_birth | B11: customers | C11: DOB | D11: Becomes customer_age | E11: n/a | F11: n/a | G11: n/a | H11: Raw date dropped
A12: claim_id | B12: claims | C12: Claim key | D12: Identifier | E12: n/a | F12: n/a | G12: n/a | H12: -
... A20: repairer_id / third_party_id | B20: claims | C20: Motor claim parties | D20: Not known for test rows | E20: n/a | F20: n/a | G20: n/a | H20: Excluded
A21: driver_age | B21: policies_motor | C21: Main driver age at row start | D21: Driver risk | E21: =IFERROR(INDEX(Features_Motor!$F:$F,MATCH($A21,Features_Motor!$A:$A,0)),"n/a") -> Include | F21: =IFERROR(INDEX(Features_Buildings!$F:$F,MATCH($A21,Features_Buildings!$A:$A,0)),"n/a") -> n/a | G21: =IFERROR(INDEX(Features_Contents!$F:$F,MATCH($A21,Features_Contents!$A:$A,0)),"n/a") -> n/a
A22: years_licensed | B22: policies_motor | C22: Years main driver licensed (capped at age-16) | D22: Driver experience | E22: =IFERROR(INDEX(Features_Motor!$F:$F,MATCH($A22,Features_Motor!$A:$A,0)),"n/a") -> Include | F22: =IFERROR(INDEX(Features_Buildings!$F:$F,MATCH($A22,Features_Buildings!$A:$A,0)),"n/a") -> n/a | G22: =IFERROR(INDEX(Features_Contents!$F:$F,MATCH($A22,Features_Contents!$A:$A,0)),"n/a") -> n/a
A23: ncb_years | B23: policies_motor | C23: No-claims bonus years | D23: Claims history / experience | E23: =IFERROR(INDEX(Features_Motor!$F:$F,MATCH($A23,Features_Motor!$A:$A,0)),"n/a") -> Include | F23: =IFERROR(INDEX(Features_Buildings!$F:$F,MATCH($A23,Features_Buildings!$A:$A,0)),"n/a") -> n/a | G23: =IFERROR(INDEX(Features_Contents!$F:$F,MATCH($A23,Features_Contents!$A:$A,0)),"n/a") -> n/a
A24: vehicle_value_group | B24: policies_motor | C24: Vehicle value band 1-20 | D24: Exposure to damage / theft severity | E24: =IFERROR(INDEX(Features_Motor!$F:$F,MATCH($A24,Features_Motor!$A:$A,0)),"n/a") -> Include | F24: =IFERROR(INDEX(Features_Buildings!$F:$F,MATCH($A24,Features_Buildings!$A:$A,0)),"n/a") -> n/a | G24: =IFERROR(INDEX(Features_Contents!$F:$F,MATCH($A24,Features_Contents!$A:$A,0)),"n/a") -> n/a
A25: vehicle_age | B25: policies_motor | C25: Vehicle age | D25: Repair cost, theft attractiveness | E25: =IFERROR(INDEX(Features_Motor!$F:$F,MATCH($A25,Features_Motor!$A:$A,0)),"n/a") -> Include | F25: =IFERROR(INDEX(Features_Buildings!$F:$F,MATCH($A25,Features_Buildings!$A:$A,0)),"n/a") -> n/a | G25: =IFERROR(INDEX(Features_Contents!$F:$F,MATCH($A25,Features_Contents!$A:$A,0)),"n/a") -> n/a
A26: make_model | B26: policies_motor | C26: Anonymised make/model code (high cardinality) | D26: Vehicle repair cost / theft target | E26: =IFERROR(INDEX(Features_Motor!$F:$F,MATCH($A26,Features_Motor!$A:$A,0)),"n/a") -> Test | F26: =IFERROR(INDEX(Features_Buildings!$F:$F,MATCH($A26,Features_Buildings!$A:$A,0)),"n/a") -> n/a | G26: =IFERROR(INDEX(Features_Contents!$F:$F,MATCH($A26,Features_Contents!$A:$A,0)),"n/a") -> n/a | H26: High cardinality - encoded by training rate order; overfit risk on sparse perils
A27: engine_size_cc | B27: policies_motor | C27: Engine size | D27: Performance / driving style | E27: =IFERROR(INDEX(Features_Motor!$F:$F,MATCH($A27,Features_Motor!$A:$A,0)),"n/a") -> Include | F27: =IFERROR(INDEX(Features_Buildings!$F:$F,MATCH($A27,Features_Buildings!$A:$A,0)),"n/a") -> n/a | G27: =IFERROR(INDEX(Features_Contents!$F:$F,MATCH($A27,Features_Contents!$A:$A,0)),"n/a") -> n/a
