Workbook

Sheet README
A1: Model iterations - score summary, improvement reasons and blend plan
A2: Purpose | B2: Track every submission's public score against its local scores, record why each change probably helped or hurt, and plan the final per-line / per-peril blend.
A3: Target | B3: Public score = Kaggle Tweedie D2 (p = 1.5), higher = better. Best so far: SAM 2 0.12796.
A4: Sources | B4: Public and local D2: submission log and BEN 1 table in docs/workflow.md (22 Oct 2026). Predicted 2025 burn costs: comparison table in R/6_export_model_spreadsheet.R (only ITER 1, ITER 2, SAM 1, SAM 2 recorded there). Code facts: model_variations_register.xlsx.
A5: Main caution | B5: Local D2 is NOT on one basis (SAM 2 and SAM 3 share 3 reported folds; WENDY 4, WENDY 5, WENDY 6 and WENDY 4 SAM02-clean share the 2024 developed fold): WENDY 4 scores developed actuals, the others reported actuals; WENDY 3 has 2024 only; SAM 2 also has 2022. Use local scores to choose components only after re-scoring every model with one shared harness (Next_Steps #1).
A6: Reasons column | B6: 'Potential reasons' are hypotheses from reading the code and the logged scores - not measured unless the evidence column says 'measured' (BEN 1 variant ladder).
A7: Editable cells | B7: Blue text on yellow fill = inputs. Iteration_Summary rows 9-12 take new submissions (formulas fill in). Blend_Peril: enter each candidate's mean out-of-fold D2 (developed actuals, 2023-24) - the best candidate fills in. Example format: 0.0612 in W4_freq_sev for motor / own_damage.
A8: Sheets | B8: Iteration_Summary | Change_Levers | Local_vs_Public | BEN1_Ladder | Line_Scores | Blend_Line | Blend_Peril | Next_Steps

Sheet Iteration_Summary
A1: # | B1: iteration | C1: date | D1: time SGT | E1: file | F1: public D2 | G1: local D2 ALL 2022 | H1: local D2 ALL 2023 | I1: local D2 ALL 2024 | J1: local actual basis | K1: motor 2023 | L1: motor 2024 | M1: buildings 2023 | N1: buildings 2024 | O1: contents 2023 | P1: contents 2024 | Q1: 2025 burn motor | R1: 2025 burn buildings | S1: 2025 burn contents | T1: key change vs parent | U1: potential reasons (hypotheses) | V1: evidence | W1: confidence | X1: change vs previous submission | Y1: change vs best before | Z1: new best? | AA1: public rank
A2: 1 | B2: ITER 1 | C2: 2026-10-20 | D2: ~14:00 | E2: submission_20261020_1400_submitted.csv | F2: 0.11904 | H2: 0.1055 | I2: 0.0944 | J2: reported | K2: 0.055 | L2: 0.045 | M2: 0.062 | N2: 0.066 | O2: 0.062 | P2: 0.061 | Q2: 518.12 | R2: 425.08 | S2: 113.2 | T2: Baseline: best of 4 candidates per line; GLM freq x sev won all lines; no trend | U2: Explainable GLM, but 2025 priced at the 2021-24 average level (no trend) and 2024 only count-developed. | V2: Local 2023 high (0.1055) yet public among the lowest -> local 2023 does not track public. | W2: - | X2: - | Y2: - | Z2: Yes (first) | AA2: =IF(F2="","",RANK(F2,$F$2:$F$16)) -> 8
A3: 2 | B3: ITER 2 | C3: 2026-10-21 | D3: n/r | E3: submission_20261021_0951.csv | F3: 0.12149 | H3: 0.0997 | I3: 0.0973 | J3: reported | K3: 0.038 | L3: 0.05 | M3: 0.07 | N3: 0.071 | O3: 0.06 | P3: 0.057 | Q3: 498.8 | R3: 434.25 | S3: 119.13 | T3: XGBoost Tweedie per line + random grid search | U3: Trees capture non-linear effects and interactions (buildings +0.008 / +0.005 for 2023 / 2024). Features include written_premium (current price), which can carry a lot of rating signal. | V3: Public +0.00245; local 2024 +0.003 but local 2023 -0.006 (motor 0.055 -> 0.038): public followed 2024, not 2023. | W3: Medium | X3: =IF(OR(F3="",F2=""),"",F3-F2) -> 0.00245 | Y3: =IF(F3="","",F3-MAX(F$2:F2)) -> 0.00245 | Z3: =IF(F3="","",IF(F3>MAX(F$2:F2),"Yes","No")) -> Yes | AA3: =IF(F3="","",RANK(F3,$F$2:$F$16)) -> 6
A4: 3 | B4: SAM 1 | C4: 2026-10-21 | D4: 13:36 | E4: submission_20261021_1336.csv | F4: 0.11876 | H4: 0.1071 | I4: 0.0959 | J4: reported | K4: 0.056 | L4: 0.045 | M4: 0.065 | N4: 0.07 | O4: 0.064 | P4: 0.062 | Q4: 518.12 | R4: 411.79 | S4: 111.8 | T4: GLM (motor) and GLM/LightGBM blend (buildings, contents) chosen by mean local D2 | U4: Selection leaned on the 2023 fold, which favours the GLM; the GLM has no trend and the blend lowered the buildings / contents level (411.79 / 111.80 vs 434.25 / 119.13 in ITER 2). Blend weights picked on the reported folds (optimistic). | V4: Public -0.00273 vs #2 despite the best local 2023 (0.1071). | W4: Medium | X4: =IF(OR(F4="",F3=""),"",F4-F3) -> -0.00273 | Y4: =IF(F4="","",F4-MAX(F$2:F3)) -> -0.00273 | Z4: =IF(F4="","",IF(F4>MAX(F$2:F3),"Yes","No")) -> No | AA4: =IF(F4="","",RANK(F4,$F$2:$F$16)) -> 9
A5: 4 | B5: WENDY 3 | C5: 2026-10-21 | D5: ~17:15 | E5: submission_20261021_1650.csv | F5: 0.12132 | I5: 0.0954 | J5: reported (2024 only) | L5: 0.043 | N5: 0.072 | P5: 0.059 | T5: One XGBoost Tweedie per peril (15), line = sum | U5: Per-peril split helps buildings / contents a little but sparse perils give tiny Tweedie trees; ~72 s tuning per motor peril; motor lost 0.007. No trend; single immature fold. | V5: Public -0.00017 vs #2; local 2024 -0.002 (motor -0.007, buildings +0.001, contents +0.002). | W5: Medium | X5: =IF(OR(F5="",F4=""),"",F5-F4) -> 0.00256 | Y5: =IF(F5="","",F5-MAX(F$2:F4)) -> -0.00017 | Z5: =IF(F5="","",IF(F5>MAX(F$2:F4),"Yes","No")) -> No | AA5: =IF(F5="","",RANK(F5,$F$2:$F$16)) -> 7
A6: 5 | B6: BEN 1 | C6: 2026-10-21 | D6: n/r | E6: submission_20261021_1658.csv | F6: 0.12224 | H6: 0.1 | I6: 0.0998 | J6: reported | K6: 0.038 | L6: 0.051 | M6: 0.069 | N6: 0.073 | O6: 0.062 | P6: 0.062 | T6: ITER 2 + EDA feature fixes, per-peril IBNR, trend to 2025, time-fold tuning, monotone, expanding window | U6: Measured: trend helps buildings / contents; time-fold tuning + monotone helps motor 2023 and contents; expanding beats rolling by 0.002-0.004 (2024). Feature fixes cost a little locally but cut 2025 drift. | V6: Public +0.00075 vs #2, in line with local gains on both years (BEN1_Ladder). | W6: High (ladder measured) | X6: =IF(OR(F6="",F5=""),"",F6-F5) -> 0.00092 | Y6: =IF(F6="","",F6-MAX(F$2:F5)) -> 0.00075 | Z6: =IF(F6="","",IF(F6>MAX(F$2:F5),"Yes","No")) -> Yes | AA6: =IF(F6="","",RANK(F6,$F$2:$F$16)) -> 5
A7: 6 | B7: WENDY 4 | C7: 2026-10-22 | D7: 07:52 | E7: submission_20261022_0715_wendy04.csv | F7: 0.12671 | H7: 0.1053 | I7: 0.1045 | J7: DEVELOPED | K7: 0.051 | L7: 0.055 | M7: 0.07 | N7: 0.071 | O7: 0.07 | P7: 0.064 | T7: Per-peril Poisson GBM freq x Gamma GBM/GLM sev (vs Tweedie challenger), ultimate frequency, severity trend, history, structural zeros | U7: Frequency fitted on exposure x reported share (ULTIMATE level), severity trended to 2025, outlier claim limited to 2m, open-claim recoveries, prior-year claims history, written_premium removed. Gini barely moved (0.502 vs 0.491 ITER 2) so most of the gain is probably LEVEL / calibration rather than ranking. | V7: Public +0.00447 vs #5 (largest single jump). Reported-basis re-score (R/4_check_reported_w4.R, 22 Oct; developed rows reproduce the card exactly): ALL 0.1028 / 0.0988 (2023 / 2024); motor 0.0403 / 0.0491, buildings 0.0706 / 0.0727, contents 0.0703 / 0.0637. Mean 0.1008 vs SAM 3 0.1015 / SAM 2 0.1014 - same order as the public board. Motor 2023 is hit by the 11.9m BI claim (raw basis has no 2m limit). | W7: Medium | X7: =IF(OR(F7="",F6=""),"",F7-F6) -> 0.00447 | Y7: =IF(F7="","",F7-MAX(F$2:F6)) -> 0.00447 | Z7: =IF(F7="","",IF(F7>MAX(F$2:F6),"Yes","No")) -> Yes | AA7: =IF(F7="","",RANK(F7,$F$2:$F$16)) -> 3
A8: 7 | B8: SAM 2 | C8: 2026-10-22 | D8: n/r | E8: submission_20261021_1528.csv | F8: 0.12796 | G8: 0.1143 | H8: 0.1045 | I8: 0.0982 | J8: reported | K8: 0.049 | L8: 0.046 | M8: 0.071 | N8: 0.071 | O8: 0.066 | P8: 0.067 | Q8: 604.13 | R8: 487.37 | S8: 125.14 | T8: Raw rebuild: claim-history features, per-peril trended GLM level, LGB/XGB frequency bags, line Tweedie bags, greedy blend | U8: Highest 2025 level of all logged runs (motor 604 vs 499-518; buildings 487 vs 412-434; contents 125 vs 112-119) from per-peril trend (+/-10%) and IBNR; rich policy / customer / address claim history; blend of 5 model types. | V8: Best public (+0.00125 vs #6, +0.00647 vs #2). Local 2024 only 4th -> gain again looks level-driven. | W8: Medium | X8: =IF(OR(F8="",F7=""),"",F8-F7) -> 0.00125 | Y8: =IF(F8="","",F8-MAX(F$2:F7)) -> 0.00125 | Z8: =IF(F8="","",IF(F8>MAX(F$2:F7),"Yes","No")) -> Yes | AA8: =IF(F8="","",RANK(F8,$F$2:$F$16)) -> 2
A9: 8 | B9: WENDY 5 | C9: 2026-10-22 | D9: n/r | E9: submission_20261022_0912_wendy05.csv | F9: 0.12636 | I9: 0.1025 | J9: DEVELOPED (time_2024) | L9: 0.052 | N9: 0.069 | P9: 0.063 | T9: WENDY 4 basis + random-search tuning per component (20 configs), severity GBM vs GLM per peril, method chosen on 5-fold policy-grouped CV over all years | U9: Same targets, features, caps, IBNR and trend as WENDY 4, so the 2025 LEVEL hardly changed - only ranking could move. Tuning optimised component deviance on a random policy fold and the method choice used folds that mix years (grouped CV 0.1118 looks much better than the 2024 time check 0.1025), which rewards fit to the past rather than the 2025 forecast. Chose freq_sev for 13/15 perils (WENDY 4: 12/15) and severity GBM for 11 perils, GLM for 4. | V9: Like-for-like with WENDY 4 on the 2024 developed fold: 0.1025 vs 0.1045 (-0.0020; motor 0.052 vs 0.055, buildings 0.069 vs 0.071, contents 0.063 vs 0.064) - local AGREES with the public drop (-0.00035). Grouped CV (not comparable): ALL 0.1118, motor 0.058, buildings 0.071, contents 0.073. MD5 33b990116f99a3b93ba90900c8864b25; replication passed. | W9: Medium | X9: =IF(OR(F9="",F8=""),"",F9-F8) -> -0.0016 | Y9: =IF(F9="","",F9-MAX(F$2:F8)) -> -0.0016 | Z9: =IF(F9="","",IF(F9>MAX(F$2:F8),"Yes","No")) -> No | AA9: =IF(F9="","",RANK(F9,$F$2:$F$16)) -> 4
A10: 9 | B10: SAM 3 | C10: 2026-10-22 | D10: 14:01 | E10: submission_20261022_1159.csv | F10: 0.12818 | G10: 0.1145 | H10: 0.1043 | I10: 0.0986 | J10: reported | K10: 0.043 | L10: 0.047 | M10: 0.071 | N10: 0.075 | O10: 0.071 | P10: 0.064 | Q10: 603.26 | R10: 487.44 | S10: 125.17 | T10: SAM 2 with ONE change: peril frequency models use observed counts over effective exposure (exposure / IBNR factor) instead of IBNR-inflated counts over exposure; same data, severity, tuning budget, blend method | U10: 2025 level is the same as SAM 2 (burn within 0.2% on every line). The expected frequency rate is unchanged; what changes is the WEIGHT - immature 2024 rows now count less in the fit, so 2024 noise (open, late claims) moves the relativities less. Blend weights shifted to peril XGB + GLM; LightGBM got 0. The gain is small and may be within noise. | V10: Public +0.00022 vs SAM 2; local ALL 2022 / 2023 / 2024 = +0.0002 / -0.0002 / +0.0004 vs SAM 2 - consistent but tiny. | W10: Low-medium | X10: =IF(OR(F10="",F9=""),"",F10-F9) -> 0.00182 | Y10: =IF(F10="","",F10-MAX(F$2:F9)) -> 0.00022 | Z10: =IF(F10="","",IF(F10>MAX(F$2:F9),"Yes","No")) -> Yes | AA10: =IF(F10="","",RANK(F10,$F$2:$F$16)) -> 1
A11: 10 | B11: WENDY 4 SAM02-clean | C11: run done - not submitted | E11: submission_<run id>_wendy04_vsam02clean.csv | I11: 0.0988 | J11: reported (2024 only) | L11: 0.0491 | N11: 0.0727 | P11: 0.0637 | T11: WENDY 4 models unchanged on SAM 2-cleaned data (controlled cleaning test) | U11: Expected: almost identical to WENDY 4 (only sum_insured rule, missing-level scope and nil-claim filter order differ). A material move would point at data cleaning, not modelling, as part of SAM 2's edge. | V11: Reported 2024 figures supplied earlier (ALL 0.0988; motor 0.0491, buildings 0.0727, contents 0.0637) are IDENTICAL to WENDY 4's own reported re-score - either they came from the WENDY 4 run or cleaning changed nothing. Confirm with R/4_check_reported_w4.R on the SAM02-clean script + the compare script. Not submitted: see Submit_Gate. | W11: - | X11: =IF(OR(F11="",F10=""),"",F11-F10) | Y11: =IF(F11="","",F11-MAX(F$2:F10)) | Z11: =IF(F11="","",IF(F11>MAX(F$2:F10),"Yes","No")) | AA11: =IF(F11="","",RANK(F11,$F$2:$F$16))
A12: 11 | B12: WENDY 6 | C12: running | E12: submission_<run id>_wendy06.csv | J12: DEVELOPED | T12: H2O AutoML per peril for frequency and severity on WENDY 5's folds; no monotone constraints | U12: Tests the learner only (same basis as WENDY 5). AutoML may rank better on data-rich perils; dropping monotone constraints and no Tweedie option can hurt sparse perils and the excess / NCB shape. | V12: Pending. Compare time_2024 peril and line D2 and component_cv with WENDY 5 (same folds and targets). | W12: - | X12: =IF(OR(F12="",F11=""),"",F12-F11) | Y12: =IF(F12="","",F12-MAX(F$2:F11)) | Z12: =IF(F12="","",IF(F12>MAX(F$2:F11),"Yes","No")) | AA12: =IF(F12="","",RANK(F12,$F$2:$F$16))
X13: =IF(OR(F13="",F12=""),"",F13-F12) | Y13: =IF(F13="","",F13-MAX(F$2:F12)) | Z13: =IF(F13="","",IF(F13>MAX(F$2:F12),"Yes","No")) | AA13: =IF(F13="","",RANK(F13,$F$2:$F$16))
X14: =IF(OR(F14="",F13=""),"",F14-F13) | Y14: =IF(F14="","",F14-MAX(F$2:F13)) | Z14: =IF(F14="","",IF(F14>MAX(F$2:F13),"Yes","No")) | AA14: =IF(F14="","",RANK(F14,$F$2:$F$16))
X15: =IF(OR(F15="",F14=""),"",F15-F14) | Y15: =IF(F15="","",F15-MAX(F$2:F14)) | Z15: =IF(F15="","",IF(F15>MAX(F$2:F14),"Yes","No")) | AA15: =IF(F15="","",RANK(F15,$F$2:$F$16))
X16: =IF(OR(F16="",F15=""),"",F16-F15) | Y16: =IF(F16="","",F16-MAX(F$2:F15)) | Z16: =IF(F16="","",IF(F16>MAX(F$2:F15),"Yes","No")) | AA16: =IF(F16="","",RANK(F16,$F$2:$F$16))
E18: Best public D2 | F18: =MAX(F2:F16) -> 0.12818
E19: Best iteration | F19: =INDEX(B2:B16,MATCH(MAX(F2:F16),F2:F16,0)) -> SAM 3
E20: Notes | F20: n/r = not recorded. Numbering follows workflow.md (22 Oct 15:14 version): SAM 2 #7, WENDY 5 #8, SAM 3 #9; #10-#11 are still running. Rows 12-16 take updates / new submissions. Blank burn cost = not recorded outside the model card (models/<iteration>/test_prediction_summary.csv was not in the zip). WENDY 3 has no 2023 fold.

Sheet Change_Levers
A1: lever | B1: used in | C1: public evidence | D1: local evidence | E1: direction | F1: confidence | G1: keep for final blend? | H1: test to confirm
A2: Level to 2025 ULTIMATE (trend + IBNR as ultimate) | B2: BEN 1 (trend), WENDY 4, SAM 2 | C2: The two best public scores (SAM 2, WENDY 4) both target ultimate and trend to 2025; SAM 2 level is about 17% / 15% / 11% above ITER 1 (motor / buildings / contents). | D2: BEN 1 v4 (+trend): buildings +0.002 both years, contents +0.002 / +0.001. | E2: Positive | F2: Medium-high | G2: Yes - one consistent level method for all components | H2: Level sensitivity on developed 2023-24 actuals: scale predictions x0.9-1.1, read D2.
A3: Tree boosting vs GLM (line level) | B3: ITER 2, BEN 1, WENDY 3 | C3: ITER 2 +0.00245 over ITER 1 GLM. | D3: 2024 +0.003; 2023 -0.006 (motor). | E3: Positive | F3: Medium | G3: Yes | H3: Common harness: tree vs GLM per line on developed actuals.
A4: Frequency x severity per peril | B4: WENDY 4, SAM 2 | C4: WENDY 4 beats WENDY 3 (Tweedie per peril) by 0.00539; freq_sev chosen for 12/15 perils. | D4: Within WENDY 4: freq_sev > Tweedie challenger on 12/15 perils (developed basis). | E4: Positive (confounded with level and history) | F4: Medium | G4: Yes | H4: Re-run WENDY 3 targets on WENDY 4's ultimate frequency to isolate.
A5: Per-peril split with Tweedie trees | B5: WENDY 3 | C5: -0.00017 vs ITER 2. | D5: Motor -0.007, buildings +0.001, contents +0.002 (2024). | E5: Neutral / negative for motor | F5: Medium | G5: Only for buildings / contents perils | H5: -
A6: Claim-history features | B6: WENDY 4 (prior year), SAM 2 (policy, customer, address) | C6: Present in the two best submissions. | D6: Not isolated. | E6: Probably positive | F6: Low-medium | G6: Yes - SAM 2 set is richer | H6: Group-drop test of hist_* in the common harness.
A7: Remove written_premium / drifting fields | B7: BEN 1, WENDY 4, SAM 2 | C7: BEN 1 up vs ITER 2 despite the removal; WENDY 4 and SAM 2 exclude it. | D7: BEN 1 v2 (feature fixes) mixed: -0.005 to +0.002 by line and year; premium_index worth 0.003-0.007. | E7: Neutral to slightly negative locally, safer for 2025 | F7: Medium | G7: Yes; test premium_index as a challenger | H7: premium_index on / off in WENDY 4 and SAM 2.
A8: Time-fold tuning + monotone constraints | B8: BEN 1 v5 | C8: Part of BEN 1's +0.00075. | D8: Motor 2023 +0.003, contents +0.004 / +0.002. | E8: Positive | F8: High (measured) | G8: Yes | H8: -
A9: Expanding vs rolling window | B9: BEN 1 v6 | C9: Expanding kept for the final fit. | D9: 2024: +0.002 motor, +0.0035 buildings, +0.003 contents. | E9: Positive | F9: High (measured) | G9: Yes - fit on 2021-24 | H9: -
A10: Blend selected on the reported folds | B10: SAM 1 | C10: -0.00273 vs ITER 2. | D10: Best local 2023 of all (0.1071). | E10: Negative | F10: Medium | G10: Choose weights on developed actuals and mostly the 2024 fold | H10: -
A11: Hyper-parameter tuning per component (random search) | B11: WENDY 5 | C11: WENDY 5 -0.00035 vs WENDY 4. | D11: Tuning gain per component in wendy_iteration_05/tuning_gain.csv. | E11: Neutral / slightly negative | F11: Low (one test, near noise) | G11: Light tuning only; defaults are close | H11: Compare WENDY 5 vs WENDY 4 per peril on the 2024 time fold.
A12: Method choice on policy-grouped CV over all years | B12: WENDY 5 | C12: Part of WENDY 5's -0.00035. | D12: WENDY 5 card: group_cv vs time_2024 picks. | E12: Unclear | F12: Low | G12: Prefer time-based choice for 2025 | H12: Count perils where group_cv and time_2024 pick different methods.
... A18: Structural zeros, open-claim recoveries | B18: WENDY 4 | C18: Not isolated. | D18: - | E18: Small | F18: Low | G18: Yes (cheap, logical) | H18: -

Sheet Local_vs_Public
A1: iteration | B1: public D2 | C1: local ALL 2023 | D1: local ALL 2024 | E1: basis | F1: rank public | G1: rank local 2023 | H1: rank local 2024
A2: ITER 1 | B2: 0.11904 | C2: 0.1055 | D2: 0.0944 | E2: reported | F2: =RANK(B2,$B$2:$B$10) -> 8 | G2: =IF(C2="","",RANK(C2,$C$2:$C$10)) -> 2 | H2: =IF(D2="","",RANK(D2,$D$2:$D$10)) -> 9
A3: ITER 2 | B3: 0.12149 | C3: 0.0997 | D3: 0.0973 | E3: reported | F3: =RANK(B3,$B$2:$B$10) -> 6 | G3: =IF(C3="","",RANK(C3,$C$2:$C$10)) -> 7 | H3: =IF(D3="","",RANK(D3,$D$2:$D$10)) -> 6
A4: SAM 1 | B4: 0.11876 | C4: 0.1071 | D4: 0.0959 | E4: reported | F4: =RANK(B4,$B$2:$B$10) -> 9 | G4: =IF(C4="","",RANK(C4,$C$2:$C$10)) -> 1 | H4: =IF(D4="","",RANK(D4,$D$2:$D$10)) -> 7
A5: WENDY 3 | B5: 0.12132 | D5: 0.0954 | E5: reported (2024 only) | F5: =RANK(B5,$B$2:$B$10) -> 7 | G5: =IF(C5="","",RANK(C5,$C$2:$C$10)) | H5: =IF(D5="","",RANK(D5,$D$2:$D$10)) -> 8
A6: BEN 1 | B6: 0.12224 | C6: 0.1 | D6: 0.0998 | E6: reported | F6: =RANK(B6,$B$2:$B$10) -> 5 | G6: =IF(C6="","",RANK(C6,$C$2:$C$10)) -> 6 | H6: =IF(D6="","",RANK(D6,$D$2:$D$10)) -> 2
A7: WENDY 4 | B7: 0.12671 | C7: 0.1028 | D7: 0.0988 | E7: reported (re-score) | F7: =RANK(B7,$B$2:$B$10) -> 3 | G7: =IF(C7="","",RANK(C7,$C$2:$C$10)) -> 5 | H7: =IF(D7="","",RANK(D7,$D$2:$D$10)) -> 3
A8: SAM 2 | B8: 0.12796 | C8: 0.1045 | D8: 0.0982 | E8: reported | F8: =RANK(B8,$B$2:$B$10) -> 2 | G8: =IF(C8="","",RANK(C8,$C$2:$C$10)) -> 3 | H8: =IF(D8="","",RANK(D8,$D$2:$D$10)) -> 5
A9: WENDY 5 | B9: 0.12636 | D9: 0.1025 | E9: DEVELOPED (time_2024) | F9: =RANK(B9,$B$2:$B$10) -> 4 | G9: =IF(C9="","",RANK(C9,$C$2:$C$10)) | H9: =IF(D9="","",RANK(D9,$D$2:$D$10)) -> 1
A10: SAM 3 | B10: 0.12818 | C10: 0.1043 | D10: 0.0986 | E10: reported | F10: =RANK(B10,$B$2:$B$10) -> 1 | G10: =IF(C10="","",RANK(C10,$C$2:$C$10)) -> 4 | H10: =IF(D10="","",RANK(D10,$D$2:$D$10)) -> 4
A13: Pearson public vs local 2024 (n = 9) | D13: =CORREL(B2:B10,D2:D10) -> 0.67220494
A14: Spearman public vs local 2024 (n = 9) | D14: =CORREL(F2:F10,H2:H10) -> 0.65
A15: Pearson public vs local 2023 (n = 7; WENDY 3 blank skipped) | D15: =CORREL(B2:B10,C2:C10) -> -0.1180957
A16: Reading | B16: Local 2024 ranks the submissions roughly like the public board; local 2023 does not (it favoured the GLMs). WENDY 4 and WENDY 5 use developed actuals (higher by construction). Only 9 points - indicative, not a test. Use 2024 (developed) as the main selection fold and 2023 as a stability check.

Sheet BEN1_Ladder
A1: variant | B1: change | C1: motor 2023 | D1: motor 2024 | E1: buildings 2023 | F1: buildings 2024 | G1: contents 2023 | H1: contents 2024 | I1: mean of 6 | J1: motor change vs previous | K1: buildings change | L1: contents change
A2: v0 | B2: ITER 2 setup, expanding window | C2: 0.0385 | D2: 0.0496 | E2: 0.0688 | F2: 0.0724 | G2: 0.0592 | H2: 0.0589 | I2: =AVERAGE(C2:H2) -> 0.0579 | J2: - | K2: - | L2: -
A3: v1 | B3: + rolling 2-year window | C3: 0.0385 | D3: 0.0479 | E3: 0.0688 | F3: 0.0696 | G3: 0.0592 | H3: 0.0545 | I3: =AVERAGE(C3:H3) -> 0.056416667 | J3: =AVERAGE(C3:D3)-AVERAGE(C2:D2) -> -0.00085 | K3: =AVERAGE(E3:F3)-AVERAGE(E2:F2) -> -0.0014 | L3: =AVERAGE(G3:H3)-AVERAGE(G2:H2) -> -0.0022
A4: v2 | B4: + EDA feature fixes | C4: 0.0337 | D4: 0.0482 | E4: 0.0676 | F4: 0.068 | G4: 0.056 | H4: 0.0567 | I4: =AVERAGE(C4:H4) -> 0.055033333 | J4: =AVERAGE(C4:D4)-AVERAGE(C3:D3) -> -0.00225 | K4: =AVERAGE(E4:F4)-AVERAGE(E3:F3) -> -0.0014 | L4: =AVERAGE(G4:H4)-AVERAGE(G3:H3) -> -0.0005
A5: v3 | B5: + IBNR by peril | C5: 0.036 | D5: 0.0475 | E5: 0.0676 | F5: 0.0676 | G5: 0.056 | H5: 0.0566 | I5: =AVERAGE(C5:H5) -> 0.055216667 | J5: =AVERAGE(C5:D5)-AVERAGE(C4:D4) -> 0.0008 | K5: =AVERAGE(E5:F5)-AVERAGE(E4:F4) -> -0.0002 | L5: =AVERAGE(G5:H5)-AVERAGE(G4:H4) -> -5e-05
A6: v4 | B6: + trend to the scored year | C6: 0.0353 | D6: 0.0489 | E6: 0.0695 | F6: 0.0695 | G6: 0.0581 | H6: 0.0574 | I6: =AVERAGE(C6:H6) -> 0.05645 | J6: =AVERAGE(C6:D6)-AVERAGE(C5:D5) -> 0.00035 | K6: =AVERAGE(E6:F6)-AVERAGE(E5:F5) -> 0.0019 | L6: =AVERAGE(G6:H6)-AVERAGE(G5:H5) -> 0.00145
A7: v5 | B7: + tuned on a time fold, monotone constraints | C7: 0.0384 | D7: 0.0494 | E7: 0.0686 | F7: 0.0696 | G7: 0.0625 | H7: 0.0598 | I7: =AVERAGE(C7:H7) -> 0.05805 | J7: =AVERAGE(C7:D7)-AVERAGE(C6:D6) -> 0.0018 | K7: =AVERAGE(E7:F7)-AVERAGE(E6:F6) -> -0.0004 | L7: =AVERAGE(G7:H7)-AVERAGE(G6:H6) -> 0.0034
A8: v6 | B8: v5 on the expanding window (selected all lines) | C8: 0.0384 | D8: 0.0514 | E8: 0.0686 | F8: 0.0731 | G8: 0.0625 | H8: 0.0625 | I8: =AVERAGE(C8:H8) -> 0.059416667 | J8: =AVERAGE(C8:D8)-AVERAGE(C7:D7) -> 0.001 | K8: =AVERAGE(E8:F8)-AVERAGE(E7:F7) -> 0.00175 | L8: =AVERAGE(G8:H8)-AVERAGE(G7:H7) -> 0.00135

Sheet Line_Scores
A1: iteration | B1: line | C1: valid_year | D1: local D2 | E1: actual basis | F1: source
A2: ITER 1 | B2: motor | C2: 2023 | D2: 0.055 | E2: reported | F2: docs/workflow.md submission log
A3: ITER 1 | B3: motor | C3: 2024 | D3: 0.045 | E3: reported | F3: docs/workflow.md submission log
A4: ITER 1 | B4: buildings | C4: 2023 | D4: 0.062 | E4: reported | F4: docs/workflow.md submission log
A5: ITER 1 | B5: buildings | C5: 2024 | D5: 0.066 | E5: reported | F5: docs/workflow.md submission log
A6: ITER 1 | B6: contents | C6: 2023 | D6: 0.062 | E6: reported | F6: docs/workflow.md submission log
A7: ITER 1 | B7: contents | C7: 2024 | D7: 0.061 | E7: reported | F7: docs/workflow.md submission log
A8: ITER 1 | B8: ALL | C8: 2023 | D8: 0.1055 | E8: reported | F8: docs/workflow.md submission log
A9: ITER 1 | B9: ALL | C9: 2024 | D9: 0.0944 | E9: reported | F9: docs/workflow.md submission log
A10: ITER 2 | B10: motor | C10: 2023 | D10: 0.038 | E10: reported | F10: docs/workflow.md submission log
A11: ITER 2 | B11: motor | C11: 2024 | D11: 0.05 | E11: reported | F11: docs/workflow.md submission log
A12: ITER 2 | B12: buildings | C12: 2023 | D12: 0.07 | E12: reported | F12: docs/workflow.md submission log
A13: ITER 2 | B13: buildings | C13: 2024 | D13: 0.071 | E13: reported | F13: docs/workflow.md submission log
... A191: WENDY 7 final2 (C5 x SAM 3) | B191: motor | C191: 2024 | D191: 0.04889 | E191: reported_raw (local protocol) | F191: output/4_check_reported/wendy07_final2/line_scores.csv

Sheet Blend_Line
A1: line | B1: ITER 1 | C1: ITER 2 | D1: SAM 1 | E1: WENDY 3 | F1: BEN 1 | G1: SAM 2 | H1: SAM 3 | I1: WENDY 4 (reported re-score) | J1: WENDY 4 | K1: WENDY 5 | L1: best mean 2023-24 (reported basis, excl. WENDY 4 / 5) | M1: best value | N1: starting hypothesis
A2: motor | B2: =IFERROR(AVERAGEIFS(Line_Scores!$D$2:$D$79,Line_Scores!$A$2:$A$79,B$1,Line_Scores!$B$2:$B$79,$A2,Line_Scores!$C$2:$C$79,">=2023"),"") -> 0.05 | C2: =IFERROR(AVERAGEIFS(Line_Scores!$D$2:$D$79,Line_Scores!$A$2:$A$79,C$1,Line_Scores!$B$2:$B$79,$A2,Line_Scores!$C$2:$C$79,">=2023"),"") -> 0.044 | D2: =IFERROR(AVERAGEIFS(Line_Scores!$D$2:$D$79,Line_Scores!$A$2:$A$79,D$1,Line_Scores!$B$2:$B$79,$A2,Line_Scores!$C$2:$C$79,">=2023"),"") -> 0.0505 | E2: =IFERROR(AVERAGEIFS(Line_Scores!$D$2:$D$79,Line_Scores!$A$2:$A$79,E$1,Line_Scores!$B$2:$B$79,$A2,Line_Scores!$C$2:$C$79,">=2023"),"") -> 0.043 | F2: =IFERROR(AVERAGEIFS(Line_Scores!$D$2:$D$79,Line_Scores!$A$2:$A$79,F$1,Line_Scores!$B$2:$B$79,$A2,Line_Scores!$C$2:$C$79,">=2023"),"") -> 0.0445 | G2: =IFERROR(AVERAGEIFS(Line_Scores!$D$2:$D$79,Line_Scores!$A$2:$A$79,G$1,Line_Scores!$B$2:$B$79,$A2,Line_Scores!$C$2:$C$79,">=2023"),"") -> 0.0475 | H2: =IFERROR(AVERAGEIFS(Line_Scores!$D$2:$D$79,Line_Scores!$A$2:$A$79,H$1,Line_Scores!$B$2:$B$79,$A2,Line_Scores!$C$2:$C$79,">=2023"),"") -> 0.045 | I2: =IFERROR(AVERAGEIFS(Line_Scores!$D$2:$D$79,Line_Scores!$A$2:$A$79,I$1,Line_Scores!$B$2:$B$79,$A2,Line_Scores!$C$2:$C$79,">=2023"),"") -> 0.0447 | ... K2: =IFERROR(AVERAGEIFS(Line_Scores!$D$2:$D$79,Line_Scores!$A$2:$A$79,K$1,Line_Scores!$B$2:$B$79,$A2,Line_Scores!$C$2:$C$79,">=2023"),"") -> 0.052 | L2: =INDEX($B$1:$I$1,MATCH(MAX(B2:I2),B2:I2,0)) -> SAM 1 | M2: =MAX(B2:I2) -> 0.0505 | N2: SAM 2 / WENDY 4 (public); ITER 1 GLM strong on 2023 -> keep a GLM component
A3: buildings | B3: =IFERROR(AVERAGEIFS(Line_Scores!$D$2:$D$79,Line_Scores!$A$2:$A$79,B$1,Line_Scores!$B$2:$B$79,$A3,Line_Scores!$C$2:$C$79,">=2023"),"") -> 0.064 | C3: =IFERROR(AVERAGEIFS(Line_Scores!$D$2:$D$79,Line_Scores!$A$2:$A$79,C$1,Line_Scores!$B$2:$B$79,$A3,Line_Scores!$C$2:$C$79,">=2023"),"") -> 0.0705 | D3: =IFERROR(AVERAGEIFS(Line_Scores!$D$2:$D$79,Line_Scores!$A$2:$A$79,D$1,Line_Scores!$B$2:$B$79,$A3,Line_Scores!$C$2:$C$79,">=2023"),"") -> 0.0675 | E3: =IFERROR(AVERAGEIFS(Line_Scores!$D$2:$D$79,Line_Scores!$A$2:$A$79,E$1,Line_Scores!$B$2:$B$79,$A3,Line_Scores!$C$2:$C$79,">=2023"),"") -> 0.072 | F3: =IFERROR(AVERAGEIFS(Line_Scores!$D$2:$D$79,Line_Scores!$A$2:$A$79,F$1,Line_Scores!$B$2:$B$79,$A3,Line_Scores!$C$2:$C$79,">=2023"),"") -> 0.071 | G3: =IFERROR(AVERAGEIFS(Line_Scores!$D$2:$D$79,Line_Scores!$A$2:$A$79,G$1,Line_Scores!$B$2:$B$79,$A3,Line_Scores!$C$2:$C$79,">=2023"),"") -> 0.071 | H3: =IFERROR(AVERAGEIFS(Line_Scores!$D$2:$D$79,Line_Scores!$A$2:$A$79,H$1,Line_Scores!$B$2:$B$79,$A3,Line_Scores!$C$2:$C$79,">=2023"),"") -> 0.073 | I3: =IFERROR(AVERAGEIFS(Line_Scores!$D$2:$D$79,Line_Scores!$A$2:$A$79,I$1,Line_Scores!$B$2:$B$79,$A3,Line_Scores!$C$2:$C$79,">=2023"),"") -> 0.07165 | ... K3: =IFERROR(AVERAGEIFS(Line_Scores!$D$2:$D$79,Line_Scores!$A$2:$A$79,K$1,Line_Scores!$B$2:$B$79,$A3,Line_Scores!$C$2:$C$79,">=2023"),"") -> 0.069 | L3: =INDEX($B$1:$I$1,MATCH(MAX(B3:I3),B3:I3,0)) -> SAM 3 | M3: =MAX(B3:I3) -> 0.073 | N3: SAM 2 / BEN 1 / WENDY 3 close; per-peril (WENDY 4, SAM 2 GLM) for fire / flood / subsidence
A4: contents | B4: =IFERROR(AVERAGEIFS(Line_Scores!$D$2:$D$79,Line_Scores!$A$2:$A$79,B$1,Line_Scores!$B$2:$B$79,$A4,Line_Scores!$C$2:$C$79,">=2023"),"") -> 0.0615 | C4: =IFERROR(AVERAGEIFS(Line_Scores!$D$2:$D$79,Line_Scores!$A$2:$A$79,C$1,Line_Scores!$B$2:$B$79,$A4,Line_Scores!$C$2:$C$79,">=2023"),"") -> 0.0585 | D4: =IFERROR(AVERAGEIFS(Line_Scores!$D$2:$D$79,Line_Scores!$A$2:$A$79,D$1,Line_Scores!$B$2:$B$79,$A4,Line_Scores!$C$2:$C$79,">=2023"),"") -> 0.063 | E4: =IFERROR(AVERAGEIFS(Line_Scores!$D$2:$D$79,Line_Scores!$A$2:$A$79,E$1,Line_Scores!$B$2:$B$79,$A4,Line_Scores!$C$2:$C$79,">=2023"),"") -> 0.059 | F4: =IFERROR(AVERAGEIFS(Line_Scores!$D$2:$D$79,Line_Scores!$A$2:$A$79,F$1,Line_Scores!$B$2:$B$79,$A4,Line_Scores!$C$2:$C$79,">=2023"),"") -> 0.062 | G4: =IFERROR(AVERAGEIFS(Line_Scores!$D$2:$D$79,Line_Scores!$A$2:$A$79,G$1,Line_Scores!$B$2:$B$79,$A4,Line_Scores!$C$2:$C$79,">=2023"),"") -> 0.0665 | H4: =IFERROR(AVERAGEIFS(Line_Scores!$D$2:$D$79,Line_Scores!$A$2:$A$79,H$1,Line_Scores!$B$2:$B$79,$A4,Line_Scores!$C$2:$C$79,">=2023"),"") -> 0.0675 | I4: =IFERROR(AVERAGEIFS(Line_Scores!$D$2:$D$79,Line_Scores!$A$2:$A$79,I$1,Line_Scores!$B$2:$B$79,$A4,Line_Scores!$C$2:$C$79,">=2023"),"") -> 0.067 | ... K4: =IFERROR(AVERAGEIFS(Line_Scores!$D$2:$D$79,Line_Scores!$A$2:$A$79,K$1,Line_Scores!$B$2:$B$79,$A4,Line_Scores!$C$2:$C$79,">=2023"),"") -> 0.063 | L4: =INDEX($B$1:$I$1,MATCH(MAX(B4:I4),B4:I4,0)) -> SAM 3 | M4: =MAX(B4:I4) -> 0.0675 | N4: WENDY 4 highest (developed basis) - confirm on common harness
A5: ALL | B5: =IFERROR(AVERAGEIFS(Line_Scores!$D$2:$D$79,Line_Scores!$A$2:$A$79,B$1,Line_Scores!$B$2:$B$79,$A5,Line_Scores!$C$2:$C$79,">=2023"),"") -> 0.09995 | C5: =IFERROR(AVERAGEIFS(Line_Scores!$D$2:$D$79,Line_Scores!$A$2:$A$79,C$1,Line_Scores!$B$2:$B$79,$A5,Line_Scores!$C$2:$C$79,">=2023"),"") -> 0.0985 | D5: =IFERROR(AVERAGEIFS(Line_Scores!$D$2:$D$79,Line_Scores!$A$2:$A$79,D$1,Line_Scores!$B$2:$B$79,$A5,Line_Scores!$C$2:$C$79,">=2023"),"") -> 0.1015 | E5: =IFERROR(AVERAGEIFS(Line_Scores!$D$2:$D$79,Line_Scores!$A$2:$A$79,E$1,Line_Scores!$B$2:$B$79,$A5,Line_Scores!$C$2:$C$79,">=2023"),"") -> 0.0954 | F5: =IFERROR(AVERAGEIFS(Line_Scores!$D$2:$D$79,Line_Scores!$A$2:$A$79,F$1,Line_Scores!$B$2:$B$79,$A5,Line_Scores!$C$2:$C$79,">=2023"),"") -> 0.0999 | G5: =IFERROR(AVERAGEIFS(Line_Scores!$D$2:$D$79,Line_Scores!$A$2:$A$79,G$1,Line_Scores!$B$2:$B$79,$A5,Line_Scores!$C$2:$C$79,">=2023"),"") -> 0.10135 | H5: =IFERROR(AVERAGEIFS(Line_Scores!$D$2:$D$79,Line_Scores!$A$2:$A$79,H$1,Line_Scores!$B$2:$B$79,$A5,Line_Scores!$C$2:$C$79,">=2023"),"") -> 0.10145 | I5: =IFERROR(AVERAGEIFS(Line_Scores!$D$2:$D$79,Line_Scores!$A$2:$A$79,I$1,Line_Scores!$B$2:$B$79,$A5,Line_Scores!$C$2:$C$79,">=2023"),"") -> 0.1008 | ... K5: =IFERROR(AVERAGEIFS(Line_Scores!$D$2:$D$79,Line_Scores!$A$2:$A$79,K$1,Line_Scores!$B$2:$B$79,$A5,Line_Scores!$C$2:$C$79,">=2023"),"") -> 0.1025 | L5: =INDEX($B$1:$I$1,MATCH(MAX(B5:I5),B5:I5,0)) -> SAM 1 | M5: =MAX(B5:I5) -> 0.1015 | N5: -
A7: Mean of the 2023 and 2024 folds from Line_Scores. WENDY 3 and WENDY 5 = 2024 only. WENDY 4 and WENDY 5 are on developed actuals (shaded) and is excluded from 'best'. Re-score all on one basis before trusting this pick.

Sheet Blend_Peril
A1: line | B1: peril | C1: claims 2021-24 (approx.) | D1: mean severity CU (approx.) | E1: W3_xgb_tweedie | F1: W4_freq_sev | G1: W4_tweedie | H1: SAM2_peril_glm | I1: SAM2_peril_lgb | J1: SAM2_peril_xgb | K1: W5_chosen | L1: W4s_chosen | M1: W6_freq_sev | N1: SAM3_peril_glm | O1: SAM3_peril_xgb | P1: NEW_1 | Q1: best component | R1: best mean D2 | S1: starting hypothesis
A2: motor | B2: own_damage | C2: 48964 | D2: 1856 | Q2: =IF(COUNT(E2:P2)=0,"enter D2",INDEX($E$1:$P$1,MATCH(MAX(E2:P2),E2:P2,0))) -> enter D2 | R2: =IF(COUNT(E2:P2)=0,"",MAX(E2:P2)) | S2: Data-rich: GBM freq x GBM sev (WENDY 4) vs SAM 2 tree freq; recoveries matter
A3: motor | B3: third_party_prop | C3: 33826 | D3: 3681 | Q3: =IF(COUNT(E3:P3)=0,"enter D2",INDEX($E$1:$P$1,MATCH(MAX(E3:P3),E3:P3,0))) -> enter D2 | R3: =IF(COUNT(E3:P3)=0,"",MAX(E3:P3)) | S3: Data-rich: WENDY 4 freq_sev or SAM 2 tree freq
A4: motor | B4: bodily_injury | C4: 7583 | D4: 21582 | Q4: =IF(COUNT(E4:P4)=0,"enter D2",INDEX($E$1:$P$1,MATCH(MAX(E4:P4),E4:P4,0))) -> enter D2 | R4: =IF(COUNT(E4:P4)=0,"",MAX(E4:P4)) | S4: Long tail + 11.9m claim: GLM severity, latest year out of severity, consistent outlier rule
A5: motor | B5: theft | C5: 6501 | D5: 6302 | Q5: =IF(COUNT(E5:P5)=0,"enter D2",INDEX($E$1:$P$1,MATCH(MAX(E5:P5),E5:P5,0))) -> enter D2 | R5: =IF(COUNT(E5:P5)=0,"",MAX(E5:P5)) | S5: Mid-size: GBM freq, GLM or GBM sev
A6: motor | B6: glass_hail | C6: 15732 | D6: 1086 | Q6: =IF(COUNT(E6:P6)=0,"enter D2",INDEX($E$1:$P$1,MATCH(MAX(E6:P6),E6:P6,0))) -> enter D2 | R6: =IF(COUNT(E6:P6)=0,"",MAX(E6:P6)) | S6: Weather-driven frequency; small severity
A7: buildings | B7: storm | C7: 7816 | D7: 3454 | Q7: =IF(COUNT(E7:P7)=0,"enter D2",INDEX($E$1:$P$1,MATCH(MAX(E7:P7),E7:P7,0))) -> enter D2 | R7: =IF(COUNT(E7:P7)=0,"",MAX(E7:P7)) | S7: Weather-driven; WENDY 4 or SAM 2
A8: buildings | B8: flood | C8: 2232 | D8: 31359 | Q8: =IF(COUNT(E8:P8)=0,"enter D2",INDEX($E$1:$P$1,MATCH(MAX(E8:P8),E8:P8,0))) -> enter D2 | R8: =IF(COUNT(E8:P8)=0,"",MAX(E8:P8)) | S8: Sparse, hazard-driven: GLM / constrained GBM with flood_zone monotone
A9: buildings | B9: escape_of_water | C9: 10137 | D9: 5733 | Q9: =IF(COUNT(E9:P9)=0,"enter D2",INDEX($E$1:$P$1,MATCH(MAX(E9:P9),E9:P9,0))) -> enter D2 | R9: =IF(COUNT(E9:P9)=0,"",MAX(E9:P9)) | S9: Data-rich: GBM freq x GBM sev
A10: buildings | B10: subsidence | C10: 1294 | D10: 23786 | Q10: =IF(COUNT(E10:P10)=0,"enter D2",INDEX($E$1:$P$1,MATCH(MAX(E10:P10),E10:P10,0))) -> enter D2 | R10: =IF(COUNT(E10:P10)=0,"",MAX(E10:P10)) | S10: Sparse + long tail: GLM short list (SAM 2) or WENDY 4 GLM sev
A11: buildings | B11: fire | C11: 1115 | D11: 51685 | Q11: =IF(COUNT(E11:P11)=0,"enter D2",INDEX($E$1:$P$1,MATCH(MAX(E11:P11),E11:P11,0))) -> enter D2 | R11: =IF(COUNT(E11:P11)=0,"",MAX(E11:P11)) | S11: Sparsest + heaviest: GLM level, lower cap (0.99)
A12: buildings | B12: accidental_damage | C12: 3848 | D12: 1218 | Q12: =IF(COUNT(E12:P12)=0,"enter D2",INDEX($E$1:$P$1,MATCH(MAX(E12:P12),E12:P12,0))) -> enter D2 | R12: =IF(COUNT(E12:P12)=0,"",MAX(E12:P12)) | S12: Structural zero without AD cover
A13: contents | B13: theft | C13: 7863 | D13: 3648 | Q13: =IF(COUNT(E13:P13)=0,"enter D2",INDEX($E$1:$P$1,MATCH(MAX(E13:P13),E13:P13,0))) -> enter D2 | R13: =IF(COUNT(E13:P13)=0,"",MAX(E13:P13)) | S13: Security level, high-value items
... A16: contents | B16: flood | C16: 1624 | D16: 9992 | Q16: =IF(COUNT(E16:P16)=0,"enter D2",INDEX($E$1:$P$1,MATCH(MAX(E16:P16),E16:P16,0))) -> enter D2 | R16: =IF(COUNT(E16:P16)=0,"",MAX(E16:P16)) | S16: Sparse: GLM short list or WENDY 4 GLM sev
A18: Enter each candidate's D2 on ONE shared basis. Ready now: the 2024 time fold on developed actuals (fit 2021-23) - WENDY 4 / WENDY 4 SAM02-clean validation_by_peril.csv (valid_year 2024, chosen method), WENDY 5 / 6 comparison/peril_scores.csv (scheme time_2024). WENDY 3 and SAM 2 need re-scoring on that basis (Next_Steps #1). Claims and severities: profiling of 20 Oct 2026 (uncapped, approximate - verify). Peril scores cannot be read from line models (ITER 1, ITER 2, SAM 1, BEN 1).

Sheet Next_Steps
A1: # | B1: step | C1: detail | D1: linked items | E1: priority
A2: 1 | B2: Shared scoring harness | C2: One R helper (e.g. R/oof_io.R): fixed folds 2023 / 2024 (fit on earlier years), D2 on reported AND developed actuals, d2 and d2_flat, Gini, A/E. Every script writes row-level OOF predictions per peril and line. WENDY 5/6 already write comparison/peril_scores.csv, line_scores.csv, component_cv.csv and test_preds_by_peril (wendy_core.R) - extend that format to the rest. | D2: CR01, CR02, CR24 | E2: High
A3: 2 | B3: Re-run every iteration through the harness | C3: ITER 2, BEN 1, WENDY 3, WENDY 4, SAM 2 at minimum (ITER 1 / SAM 1 as GLM references), with voluntary_excess in every frequency and severity model. | D3: Excess_Treatment gaps | E3: High
A4: 3 | B4: Fill Blend_Peril and Blend_Line | C4: Per peril: pick the best component (or a 2-3 model blend) on developed mean D2; per line: compare sum-of-perils vs line models. | D4: - | E4: High
A5: 4 | B5: Separate shape from level | C5: Choose ranking components on calibrated D2, then set each line's 2025 level once (ultimate + trend), as SAM 2 does. Test level x0.9-1.1. | D5: Change_Levers #1 | E5: High
A6: 5 | B6: Fix code issues before the final fit | C6: noise_probe (CR12), drift fields in SAM 2 (CR13), BEN 1 IBNR weighting (CR10), WENDY 4 replication (CR17). | D6: Code_Review | E6: Medium
A7: 6 | B7: Final blend script | C7: R/4_models_iterfinal01.R: loads the chosen fitted components, applies per-peril / per-line weights from this workbook, one level step, replication check, submission log row. | D7: - | E7: Medium
A8: 7 | B8: Log every new submission | C8: Add a row in Iteration_Summary (rows 9-12) and in docs/workflow.md. | D8: - | E8: Ongoing
A9: 8 | B9: Bootstrap noise threshold for Submit_Gate | C9: Save row-level 2024 predictions of both models (same rows), then: library(data.table); set.seed(1); pol <- unique(v$policy_id); d <- replicate(200, { s <- v[policy_id %in% sample(pol, replace = TRUE)]; d2(s$actual, s$pred_a, s$exposure) - d2(s$actual, s$pred_b, s$exposure) }); sd(d) = standard error; put 2 x sd(d) in Submit_Gate!B1. (Sampling policies with replacement and filtering keeps each policy once; a strict bootstrap would repeat drawn policies - verify the approach suits your D2 function.) | D9: Submit_Gate | E9: High

Sheet Submit_Gate
A1: Noise threshold (local D2) | B1: 0.0011 | C1: Measured 22 Oct (R/4_compare_wendy07.R, 200 policy draws, mean 2023-24 reported_raw): 2 x bootstrap SE of the ALL difference is 0.0004-0.0011 depending on the pair; 0.0011 is the largest (WENDY 7 variants vs A0). Use each pair's own 2 x SE from output/4_check_reported/compare_wendy07_vs_*.csv where given.
A2: candidate | B2: comparator | C2: actual basis | D2: fold | E2: candidate local D2 ALL | F2: comparator local D2 ALL | G2: difference | H2: decision | I2: note
A3: WENDY 4 SAM02-clean | B3: SAM 3 (best public) | C3: reported | D3: 2024 | E3: 0.0988 | F3: 0.0986 | G3: =IF(OR(E3="",F3=""),"",E3-F3) -> 0.0002 | H3: =IF(G3="","",IF(RIGHT(C3,1)="?","Fix basis first",IF(ABS(G3)<$B$1,"Hold - within noise",IF(G3>0,"Submit","Do not submit (worse)")))) -> Hold - within noise | I3: User re-run 22 Oct; SAM 3 from workflow.md
A4: WENDY 4 SAM02-clean | B4: SAM 2 | C4: reported | D4: 2024 | E4: 0.0988 | F4: 0.0982 | G4: =IF(OR(E4="",F4=""),"",E4-F4) -> 0.0006 | H4: =IF(G4="","",IF(RIGHT(C4,1)="?","Fix basis first",IF(ABS(G4)<$B$1,"Hold - within noise",IF(G4>0,"Submit","Do not submit (worse)")))) -> Hold - within noise
A5: WENDY 4 SAM02-clean | B5: WENDY 4 (reported re-score) | C5: reported | D5: 2024 | E5: 0.0988 | F5: 0.0988 | G5: =IF(OR(E5="",F5=""),"",E5-F5) -> 0 | H5: =IF(G5="","",IF(RIGHT(C5,1)="?","Fix basis first",IF(ABS(G5)<$B$1,"Hold - within noise",IF(G5>0,"Submit","Do not submit (worse)")))) -> Hold - within noise | I5: Identical to 4 decimals - cleaning made no visible difference (confirm with the compare script)
A6: WENDY 4 (reported re-score) | B6: SAM 3 | C6: reported | D6: 2023-24 mean | E6: 0.1008 | F6: 0.10145 | G6: =IF(OR(E6="",F6=""),"",E6-F6) -> -0.00065 | H6: =IF(G6="","",IF(RIGHT(C6,1)="?","Fix basis first",IF(ABS(G6)<$B$1,"Hold - within noise",IF(G6>0,"Submit","Do not submit (worse)")))) -> Hold - within noise | I6: Back-test: public WENDY 4 0.12671 < SAM 3 0.12818 - same direction
A7: WENDY 5 | B7: WENDY 4 | C7: developed | D7: 2024 | E7: 0.1025 | F7: 0.1045 | G7: =IF(OR(E7="",F7=""),"",E7-F7) -> -0.002 | H7: =IF(G7="","",IF(RIGHT(C7,1)="?","Fix basis first",IF(ABS(G7)<$B$1,"Hold - within noise",IF(G7>0,"Submit","Do not submit (worse)")))) -> Do not submit (worse) | I7: Back-test: public later fell -0.00035, so the gate would have saved this submission
A8: SAM 3 | B8: SAM 2 | C8: reported | D8: 2024 | E8: 0.0986 | F8: 0.0982 | G8: =IF(OR(E8="",F8=""),"",E8-F8) -> 0.0004 | H8: =IF(G8="","",IF(RIGHT(C8,1)="?","Fix basis first",IF(ABS(G8)<$B$1,"Hold - within noise",IF(G8>0,"Submit","Do not submit (worse)")))) -> Hold - within noise | I8: Back-test: public later rose +0.00022 (a tie in practice)
A9: WENDY 6 | B9: WENDY 5 / WENDY 4 | C9: developed | D9: 2024 | G9: =IF(OR(E9="",F9=""),"",E9-F9) | H9: =IF(G9="","",IF(RIGHT(C9,1)="?","Fix basis first",IF(ABS(G9)<$B$1,"Hold - within noise",IF(G9>0,"Submit","Do not submit (worse)")))) | I9: Fill when the run finishes (comparison/line_scores.csv, scheme time_2024)
A10: WENDY 7 final (0.5 C4 + 0.5 SAM 3) | B10: SAM 3 (best public, rerun) | C10: reported_raw | D10: 2023-24 mean | E10: 0.10228055 | F10: 0.1013507 | G10: 0.0009298531 | H10: Submitted #10 - public 0.12924 (+0.00106 vs SAM 3) | I10: +0.00093 > pair 2 x SE 0.00047, 100% of draws; cross-fold gain positive in 6/6; file submission_20261022_2135_wendy07_final.csv
A11: WENDY 7 C4 (alone) | B11: SAM 3 (best public, rerun) | C11: reported_raw | D11: 2023-24 mean | E11: 0.10142685 | F11: 0.1013507 | G11: 7.6151314e-05 | H11: Hold - within noise | I11: Only worth submitting as part of the blend
A12: WENDY 7 A1 | B12: WENDY 7 A0 | C12: reported_raw | D12: 2023-24 mean | E12: 0.10139701 | F12: 0.10135903 | G12: 3.7978331e-05 | H12: Hold - within noise | I12: IBNR: judge on docs/wendy07_experiment_log.md step 6 backtest instead
A13: WENDY 7 A2 | B13: WENDY 7 A0 | C13: reported_raw | D13: 2023-24 mean | E13: 0.10149565 | F13: 0.10135903 | G13: 0.00013661941 | H13: Hold - within noise | I13: IBNR: chain ladder adopted on the backtest, not on D2
A14: WENDY 7 B6 | B14: WENDY 7 A0 | C14: reported_raw | D14: 2023-24 mean | E14: 0.10237513 | F14: 0.10135903 | G14: 0.0010160995 | H14: Hold - within noise | I14: Borderline (+0.00102 vs 0.00107), 100% of draws; kept in the final model
A15: WENDY 7 final2 (C5 x SAM 3) | B15: #10 WENDY 7 final (public 0.12924) | C15: reported_raw | D15: 2023-24 mean | E15: 0.10302078 | F15: 0.10228055 | G15: 0.00074022676 | H15: On hold (Wendy, 23 Oct) - passes gate vs #10, not submitted | I15: +0.00074 > pair 2 x SE 0.00051, 100% of draws; file submission_20261022_2328_wendy07_final2.csv
A16: WENDY 7 C5 (alone) | B16: #10 WENDY 7 final (public 0.12924) | C16: reported_raw | D16: 2023-24 mean | E16: 0.10255287 | F16: 0.10228055 | G16: 0.00027231383 | H16: Hold - within noise | I16: Only as part of the blend

Sheet SAM3_Components
A1: valid_year | B1: line | C1: model | D1: d2 (reported) | E1: d2_cal | F1: gini | G1: A/E developed | I1: line | J1: model | K1: mean d2_cal 2022-24 | L1: mean d2 2022-24 | M1: d2 2024 | N1: blend weight
A2: 2022 | B2: motor | C2: blend | D2: 0.059472949 | E2: 0.059444896 | F2: 0.41790455 | G2: 0.96862256 | I2: motor | J2: blend | K2: =AVERAGEIFS($E$2:$E$100,$B$2:$B$100,I2,$C$2:$C$100,J2) -> 0.053469094 | L2: =AVERAGEIFS($D$2:$D$100,$B$2:$B$100,I2,$C$2:$C$100,J2) -> 0.049584493 | M2: =SUMIFS($D$2:$D$100,$B$2:$B$100,I2,$C$2:$C$100,J2,$A$2:$A$100,2024) -> 0.046527824 | N2: 1
A3: 2022 | B3: motor | C3: peril_glm | D3: 0.055732204 | E3: 0.055880206 | F3: 0.40984646 | G3: 0.96930374 | I3: motor | J3: peril_glm | K3: =AVERAGEIFS($E$2:$E$100,$B$2:$B$100,I3,$C$2:$C$100,J3) -> 0.050517099 | L3: =AVERAGEIFS($D$2:$D$100,$B$2:$B$100,I3,$C$2:$C$100,J3) -> 0.047038528 | M3: =SUMIFS($D$2:$D$100,$B$2:$B$100,I3,$C$2:$C$100,J3,$A$2:$A$100,2024) -> 0.042238505 | N3: 0.4
A4: 2022 | B4: motor | C4: peril_lgb | D4: 0.049577368 | E4: 0.04955262 | F4: 0.39372638 | G4: 0.96796909 | I4: motor | J4: peril_lgb | K4: =AVERAGEIFS($E$2:$E$100,$B$2:$B$100,I4,$C$2:$C$100,J4) -> 0.04217814 | L4: =AVERAGEIFS($D$2:$D$100,$B$2:$B$100,I4,$C$2:$C$100,J4) -> 0.038107882 | M4: =SUMIFS($D$2:$D$100,$B$2:$B$100,I4,$C$2:$C$100,J4,$A$2:$A$100,2024) -> 0.041855768 | N4: 0
A5: 2022 | B5: motor | C5: peril_xgb | D5: 0.060488583 | E5: 0.060454016 | F5: 0.41960365 | G5: 0.9676008 | I5: motor | J5: peril_xgb | K5: =AVERAGEIFS($E$2:$E$100,$B$2:$B$100,I5,$C$2:$C$100,J5) -> 0.051623443 | L5: =AVERAGEIFS($D$2:$D$100,$B$2:$B$100,I5,$C$2:$C$100,J5) -> 0.047705023 | M5: =SUMIFS($D$2:$D$100,$B$2:$B$100,I5,$C$2:$C$100,J5,$A$2:$A$100,2024) -> 0.046940393 | N5: 0.4
A6: 2022 | B6: motor | C6: lgb_tweedie | D6: 0.035916473 | E6: 0.035893543 | F6: 0.35876032 | G6: 0.96930374 | I6: motor | J6: lgb_tweedie | K6: =AVERAGEIFS($E$2:$E$100,$B$2:$B$100,I6,$C$2:$C$100,J6) -> 0.035941196 | L6: =AVERAGEIFS($D$2:$D$100,$B$2:$B$100,I6,$C$2:$C$100,J6) -> 0.032033984 | M6: =SUMIFS($D$2:$D$100,$B$2:$B$100,I6,$C$2:$C$100,J6,$A$2:$A$100,2024) -> 0.038306223 | N6: 0
A7: 2022 | B7: motor | C7: xgb_tweedie | D7: 0.049104933 | E7: 0.049198711 | F7: 0.3930599 | G7: 0.96930374 | I7: motor | J7: xgb_tweedie | K7: =AVERAGEIFS($E$2:$E$100,$B$2:$B$100,I7,$C$2:$C$100,J7) -> 0.048718844 | L7: =AVERAGEIFS($D$2:$D$100,$B$2:$B$100,I7,$C$2:$C$100,J7) -> 0.044868111 | M7: =SUMIFS($D$2:$D$100,$B$2:$B$100,I7,$C$2:$C$100,J7,$A$2:$A$100,2024) -> 0.04521213 | N7: 0.2
A8: 2022 | B8: motor | C8: burn_cost | D8: -0.00013086891 | E8: -2.220446e-16 | F8: 0.18527949 | G8: 0.97716085 | I8: motor | J8: legacy_glm | K8: =AVERAGEIFS($E$2:$E$100,$B$2:$B$100,I8,$C$2:$C$100,J8) -> 0.053842089 | L8: =AVERAGEIFS($D$2:$D$100,$B$2:$B$100,I8,$C$2:$C$100,J8) -> 0.051885132 | M8: =SUMIFS($D$2:$D$100,$B$2:$B$100,I8,$C$2:$C$100,J8,$A$2:$A$100,2024) -> 0.044631351 | N8: -
A9: 2022 | B9: motor | C9: burn_trend | D9: -0.00012933325 | E9: -2.220446e-16 | F9: 0.18527949 | G9: 0.97731529 | I9: motor | J9: legacy_xgb | K9: =AVERAGEIFS($E$2:$E$100,$B$2:$B$100,I9,$C$2:$C$100,J9) -> 0.049611533 | L9: =AVERAGEIFS($D$2:$D$100,$B$2:$B$100,I9,$C$2:$C$100,J9) -> 0.046015646 | M9: =SUMIFS($D$2:$D$100,$B$2:$B$100,I9,$C$2:$C$100,J9,$A$2:$A$100,2024) -> 0.04947573 | N9: -
A10: 2022 | B10: motor | C10: legacy_glm | D10: 0.05529148 | E10: 0.055603642 | F10: 0.41072461 | G10: 0.95817893 | I10: motor | J10: burn_trend | K10: =AVERAGEIFS($E$2:$E$100,$B$2:$B$100,I10,$C$2:$C$100,J10) -> -3.7007434e-17 | L10: =AVERAGEIFS($D$2:$D$100,$B$2:$B$100,I10,$C$2:$C$100,J10) -> -0.0044161749 | M10: =SUMIFS($D$2:$D$100,$B$2:$B$100,I10,$C$2:$C$100,J10,$A$2:$A$100,2024) -> -0.013116012 | N10: -
A11: 2022 | B11: motor | C11: legacy_xgb | D11: 0.046825621 | E11: 0.050651164 | F11: 0.39888314 | G11: 0.8643952 | I11: buildings | J11: blend | K11: =AVERAGEIFS($E$2:$E$100,$B$2:$B$100,I11,$C$2:$C$100,J11) -> 0.070983992 | L11: =AVERAGEIFS($D$2:$D$100,$B$2:$B$100,I11,$C$2:$C$100,J11) -> 0.070795242 | M11: =SUMIFS($D$2:$D$100,$B$2:$B$100,I11,$C$2:$C$100,J11,$A$2:$A$100,2024) -> 0.074796502 | N11: 1
A12: 2022 | B12: motor | C12: peril_glm_notrend | D12: 0.055732204 | E12: 0.055880206 | F12: 0.40984646 | G12: 0.96930374 | I12: buildings | J12: peril_glm | K12: =AVERAGEIFS($E$2:$E$100,$B$2:$B$100,I12,$C$2:$C$100,J12) -> 0.067196959 | L12: =AVERAGEIFS($D$2:$D$100,$B$2:$B$100,I12,$C$2:$C$100,J12) -> 0.066972092 | M12: =SUMIFS($D$2:$D$100,$B$2:$B$100,I12,$C$2:$C$100,J12,$A$2:$A$100,2024) -> 0.069732578 | N12: 0.2
A13: 2022 | B13: buildings | C13: blend | D13: 0.066201621 | E13: 0.066397745 | F13: 0.42637513 | G13: 0.95801013 | I13: buildings | J13: peril_lgb | K13: =AVERAGEIFS($E$2:$E$100,$B$2:$B$100,I13,$C$2:$C$100,J13) -> 0.066941527 | L13: =AVERAGEIFS($D$2:$D$100,$B$2:$B$100,I13,$C$2:$C$100,J13) -> 0.066792778 | M13: =SUMIFS($D$2:$D$100,$B$2:$B$100,I13,$C$2:$C$100,J13,$A$2:$A$100,2024) -> 0.070956424 | N13: 0
A14: 2022 | B14: buildings | C14: peril_glm | D14: 0.062713698 | E14: 0.063075431 | F14: 0.41648427 | G14: 0.96161686 | I14: buildings | J14: peril_xgb | K14: =AVERAGEIFS($E$2:$E$100,$B$2:$B$100,I14,$C$2:$C$100,J14) -> 0.070499631 | L14: =AVERAGEIFS($D$2:$D$100,$B$2:$B$100,I14,$C$2:$C$100,J14) -> 0.070296715 | M14: =SUMIFS($D$2:$D$100,$B$2:$B$100,I14,$C$2:$C$100,J14,$A$2:$A$100,2024) -> 0.074812927 | N14: 0.7
A15: 2022 | B15: buildings | C15: peril_lgb | D15: 0.063378092 | E15: 0.063576025 | F15: 0.41809372 | G15: 0.95640275 | I15: buildings | J15: lgb_tweedie | K15: =AVERAGEIFS($E$2:$E$100,$B$2:$B$100,I15,$C$2:$C$100,J15) -> 0.062283137 | L15: =AVERAGEIFS($D$2:$D$100,$B$2:$B$100,I15,$C$2:$C$100,J15) -> 0.06206139 | M15: =SUMIFS($D$2:$D$100,$B$2:$B$100,I15,$C$2:$C$100,J15,$A$2:$A$100,2024) -> 0.066633322 | N15: 0
A16: 2022 | B16: buildings | C16: peril_xgb | D16: 0.065253483 | E16: 0.065529536 | F16: 0.4250318 | G16: 0.95646439 | I16: buildings | J16: xgb_tweedie | K16: =AVERAGEIFS($E$2:$E$100,$B$2:$B$100,I16,$C$2:$C$100,J16) -> 0.066554739 | L16: =AVERAGEIFS($D$2:$D$100,$B$2:$B$100,I16,$C$2:$C$100,J16) -> 0.066384736 | M16: =SUMIFS($D$2:$D$100,$B$2:$B$100,I16,$C$2:$C$100,J16,$A$2:$A$100,2024) -> 0.072647597 | N16: 0.1
A17: 2022 | B17: buildings | C17: lgb_tweedie | D17: 0.05820288 | E17: 0.058343339 | F17: 0.39978316 | G17: 0.96161686 | I17: buildings | J17: legacy_glm | K17: =AVERAGEIFS($E$2:$E$100,$B$2:$B$100,I17,$C$2:$C$100,J17) -> 0.059508235 | L17: =AVERAGEIFS($D$2:$D$100,$B$2:$B$100,I17,$C$2:$C$100,J17) -> 0.059746161 | M17: =SUMIFS($D$2:$D$100,$B$2:$B$100,I17,$C$2:$C$100,J17,$A$2:$A$100,2024) -> 0.068697355 | N17: -
A18: 2022 | B18: buildings | C18: xgb_tweedie | D18: 0.060216512 | E18: 0.06030258 | F18: 0.40802118 | G18: 0.96161686 | I18: buildings | J18: legacy_xgb | K18: =AVERAGEIFS($E$2:$E$100,$B$2:$B$100,I18,$C$2:$C$100,J18) -> 0.067463579 | L18: =AVERAGEIFS($D$2:$D$100,$B$2:$B$100,I18,$C$2:$C$100,J18) -> 0.066436319 | M18: =SUMIFS($D$2:$D$100,$B$2:$B$100,I18,$C$2:$C$100,J18,$A$2:$A$100,2024) -> 0.073021804 | N18: -
A19: 2022 | B19: buildings | C19: burn_cost | D19: -0.00040358307 | E19: 0 | F19: 0.15684261 | G19: 0.95239751 | I19: buildings | J19: burn_trend | K19: =AVERAGEIFS($E$2:$E$100,$B$2:$B$100,I19,$C$2:$C$100,J19) -> 0 | L19: =AVERAGEIFS($D$2:$D$100,$B$2:$B$100,I19,$C$2:$C$100,J19) -> -0.00015460154 | M19: =SUMIFS($D$2:$D$100,$B$2:$B$100,I19,$C$2:$C$100,J19,$A$2:$A$100,2024) -> -6.4134017e-05 | N19: -
A20: 2022 | B20: buildings | C20: burn_trend | D20: -0.00040358307 | E20: 0 | F20: 0.15684261 | G20: 0.95239751 | I20: contents | J20: blend | K20: =AVERAGEIFS($E$2:$E$100,$B$2:$B$100,I20,$C$2:$C$100,J20) -> 0.066656925 | L20: =AVERAGEIFS($D$2:$D$100,$B$2:$B$100,I20,$C$2:$C$100,J20) -> 0.066322355 | M20: =SUMIFS($D$2:$D$100,$B$2:$B$100,I20,$C$2:$C$100,J20,$A$2:$A$100,2024) -> 0.064249846 | N20: 1
A21: 2022 | B21: buildings | C21: legacy_glm | D21: 0.048299159 | E21: 0.047422302 | F21: 0.3921502 | G21: 1.0492813 | I21: contents | J21: peril_glm | K21: =AVERAGEIFS($E$2:$E$100,$B$2:$B$100,I21,$C$2:$C$100,J21) -> 0.06313216 | L21: =AVERAGEIFS($D$2:$D$100,$B$2:$B$100,I21,$C$2:$C$100,J21) -> 0.062786606 | M21: =SUMIFS($D$2:$D$100,$B$2:$B$100,I21,$C$2:$C$100,J21,$A$2:$A$100,2024) -> 0.06200419 | N21: 0.3
A22: 2022 | B22: buildings | C22: legacy_xgb | D22: 0.056435472 | E22: 0.058936796 | F22: 0.40366861 | G22: 0.8682844 | I22: contents | J22: peril_lgb | K22: =AVERAGEIFS($E$2:$E$100,$B$2:$B$100,I22,$C$2:$C$100,J22) -> 0.062461174 | L22: =AVERAGEIFS($D$2:$D$100,$B$2:$B$100,I22,$C$2:$C$100,J22) -> 0.062180183 | M22: =SUMIFS($D$2:$D$100,$B$2:$B$100,I22,$C$2:$C$100,J22,$A$2:$A$100,2024) -> 0.058582335 | N22: 0
A23: 2022 | B23: buildings | C23: peril_glm_notrend | D23: 0.062713698 | E23: 0.063075431 | F23: 0.41648427 | G23: 0.96161686 | I23: contents | J23: peril_xgb | K23: =AVERAGEIFS($E$2:$E$100,$B$2:$B$100,I23,$C$2:$C$100,J23) -> 0.065119614 | L23: =AVERAGEIFS($D$2:$D$100,$B$2:$B$100,I23,$C$2:$C$100,J23) -> 0.064783264 | M23: =SUMIFS($D$2:$D$100,$B$2:$B$100,I23,$C$2:$C$100,J23,$A$2:$A$100,2024) -> 0.061915668 | N23: 0.4
A24: 2022 | B24: contents | C24: blend | D24: 0.063754606 | E24: 0.063778148 | F24: 0.44290682 | G24: 1.0086491 | I24: contents | J24: lgb_tweedie | K24: =AVERAGEIFS($E$2:$E$100,$B$2:$B$100,I24,$C$2:$C$100,J24) -> 0.057275658 | L24: =AVERAGEIFS($D$2:$D$100,$B$2:$B$100,I24,$C$2:$C$100,J24) -> 0.056884383 | M24: =SUMIFS($D$2:$D$100,$B$2:$B$100,I24,$C$2:$C$100,J24,$A$2:$A$100,2024) -> 0.057447282 | N24: 0
A25: 2022 | B25: contents | C25: peril_glm | D25: 0.058480642 | E25: 0.058416755 | F25: 0.4331717 | G25: 1.0084529 | I25: contents | J25: xgb_tweedie | K25: =AVERAGEIFS($E$2:$E$100,$B$2:$B$100,I25,$C$2:$C$100,J25) -> 0.063250765 | L25: =AVERAGEIFS($D$2:$D$100,$B$2:$B$100,I25,$C$2:$C$100,J25) -> 0.062836145 | M25: =SUMIFS($D$2:$D$100,$B$2:$B$100,I25,$C$2:$C$100,J25,$A$2:$A$100,2024) -> 0.061775333 | N25: 0.3
A26: 2022 | B26: contents | C26: peril_lgb | D26: 0.060871593 | E26: 0.06086424 | F26: 0.43608903 | G26: 1.0084265 | I26: contents | J26: legacy_glm | K26: =AVERAGEIFS($E$2:$E$100,$B$2:$B$100,I26,$C$2:$C$100,J26) -> 0.060468835 | L26: =AVERAGEIFS($D$2:$D$100,$B$2:$B$100,I26,$C$2:$C$100,J26) -> 0.059774179 | M26: =SUMIFS($D$2:$D$100,$B$2:$B$100,I26,$C$2:$C$100,J26,$A$2:$A$100,2024) -> 0.060772742 | N26: -
A27: 2022 | B27: contents | C27: peril_xgb | D27: 0.062737178 | E27: 0.062748859 | F27: 0.4401312 | G27: 1.0089433 | I27: contents | J27: legacy_xgb | K27: =AVERAGEIFS($E$2:$E$100,$B$2:$B$100,I27,$C$2:$C$100,J27) -> 0.058996163 | L27: =AVERAGEIFS($D$2:$D$100,$B$2:$B$100,I27,$C$2:$C$100,J27) -> 0.05702016 | M27: =SUMIFS($D$2:$D$100,$B$2:$B$100,I27,$C$2:$C$100,J27,$A$2:$A$100,2024) -> 0.058861296 | N27: -
A28: 2022 | B28: contents | C28: lgb_tweedie | D28: 0.051919741 | E28: 0.052024243 | F28: 0.4183172 | G28: 1.0084529 | I28: contents | J28: burn_trend | K28: =AVERAGEIFS($E$2:$E$100,$B$2:$B$100,I28,$C$2:$C$100,J28) -> 3.7007434e-17 | L28: =AVERAGEIFS($D$2:$D$100,$B$2:$B$100,I28,$C$2:$C$100,J28) -> -0.00072499093 | M28: =SUMIFS($D$2:$D$100,$B$2:$B$100,I28,$C$2:$C$100,J28,$A$2:$A$100,2024) -> -5.6447286e-05 | N28: -
A29: 2022 | B29: contents | C29: xgb_tweedie | D29: 0.060874232 | E29: 0.060918906 | F29: 0.43611011 | G29: 1.0084529
A30: 2022 | B30: contents | C30: burn_cost | D30: 3.9756225e-07 | E30: 0 | F30: 0.18512365 | G30: 0.99970635 | I30: Source: sam_iteration_03_model_summary.xlsx (Validation, Blend weights). Reported actuals; d2_cal removes the level (ranking only). Legacy = SAM's replays of ITER 1 GLM / ITER 2 XGBoost on the same folds.
A31: 2022 | B31: contents | C31: burn_trend | D31: 3.9756225e-07 | E31: 1.110223e-16 | F31: 0.18512365 | G31: 0.99970635
A32: 2022 | B32: contents | C32: legacy_glm | D32: 0.055465804 | E32: 0.055390105 | F32: 0.42484916 | G32: 1.009028
A33: 2022 | B33: contents | C33: legacy_xgb | D33: 0.051127403 | E33: 0.053284482 | F33: 0.41901205 | G33: 0.90958828
A34: 2022 | B34: contents | C34: peril_glm_notrend | D34: 0.058480642 | E34: 0.058416755 | F34: 0.4331717 | G34: 1.0084529
A35: 2023 | B35: motor | C35: blend | D35: 0.042752707 | E35: 0.04305509 | F35: 0.38305896 | G35: 0.94791336
A36: 2023 | B36: motor | C36: peril_glm | D36: 0.043144875 | E36: 0.043482554 | F36: 0.39140141 | G36: 0.94739547
A37: 2023 | B37: motor | C37: peril_lgb | D37: 0.022890509 | E37: 0.023219415 | F37: 0.30619306 | G37: 0.94825157
A38: 2023 | B38: motor | C38: peril_xgb | D38: 0.035686093 | E38: 0.036121789 | F38: 0.35863336 | G38: 0.94869018
A39: 2023 | B39: motor | C39: lgb_tweedie | D39: 0.021879257 | E39: 0.022298462 | F39: 0.31169704 | G39: 0.94739547
A40: 2023 | B40: motor | C40: xgb_tweedie | D40: 0.04028727 | E40: 0.040679405 | F40: 0.37774122 | G40: 0.94739547
...
